[Tue May 31 18:24:16.725466 2022] [wsgi:error] [pid 265853] [client 127.0.0.1:32990] Target WSGI script not found or unable to stat: /home/freddy/www/multitenant/wsgi.py
[Tue May 31 18:24:16.727176 2022] [wsgi:error] [pid 265853] [client 127.0.0.1:32990] Target WSGI script not found or unable to stat: /home/freddy/www/multitenant/wsgi.py
[Tue May 31 18:24:16.862932 2022] [wsgi:error] [pid 265853] [client 127.0.0.1:32990] Target WSGI script not found or unable to stat: /home/freddy/www/multitenant/wsgi.py, referer: http://multi.mydev/
[Tue May 31 18:24:23.327955 2022] [wsgi:error] [pid 265852] [client 127.0.0.1:32992] Target WSGI script not found or unable to stat: /home/freddy/www/multitenant/wsgi.py
[Tue May 31 18:24:31.374916 2022] [wsgi:error] [pid 265854] [client 127.0.0.1:32994] Target WSGI script not found or unable to stat: /home/freddy/www/multitenant/wsgi.py
[Tue May 31 18:25:23.262551 2022] [wsgi:error] [pid 266383] [client 127.0.0.1:32998] Target WSGI script not found or unable to stat: /home/freddy/www/multitenant/wsgi.py
[Tue May 31 18:25:23.890154 2022] [wsgi:error] [pid 266383] [client 127.0.0.1:32998] Target WSGI script not found or unable to stat: /home/freddy/www/multitenant/wsgi.py
[Tue May 31 18:26:21.389431 2022] [wsgi:error] [pid 266820] [client 127.0.0.1:33004] Target WSGI script not found or unable to stat: /home/freddy/www/multitenant/wsgi.py
[Tue May 31 18:26:21.945414 2022] [wsgi:error] [pid 266820] [client 127.0.0.1:33004] Target WSGI script not found or unable to stat: /home/freddy/www/multitenant/wsgi.py
[Tue May 31 18:26:22.161765 2022] [wsgi:error] [pid 266820] [client 127.0.0.1:33004] Target WSGI script not found or unable to stat: /home/freddy/www/multitenant/wsgi.py
[Tue May 31 18:26:22.295096 2022] [wsgi:error] [pid 266820] [client 127.0.0.1:33004] Target WSGI script not found or unable to stat: /home/freddy/www/multitenant/wsgi.py
[Tue May 31 18:31:32.004946 2022] [wsgi:error] [pid 268706] [client 127.0.0.1:33016] Target WSGI script not found or unable to stat: /home/freddy/www/multitenant/wsgi.py
[Tue May 31 18:31:32.725733 2022] [wsgi:error] [pid 268706] [client 127.0.0.1:33016] Target WSGI script not found or unable to stat: /home/freddy/www/multitenant/wsgi.py
[Tue May 31 23:45:26.609713 2022] [wsgi:error] [pid 1089] [client 127.0.0.1:42916] Target WSGI script not found or unable to stat: /home/freddy/www/multitenant/wsgi.py
[Tue May 31 23:45:26.765432 2022] [wsgi:error] [pid 1089] [client 127.0.0.1:42916] Target WSGI script not found or unable to stat: /home/freddy/www/multitenant/wsgi.py, referer: http://multi.mydev/
[Tue May 31 23:49:09.116384 2022] [wsgi:error] [pid 11244] [client 127.0.0.1:42920] Target WSGI script not found or unable to stat: /home/freddy/www/multitenant/wsgi.py
[Tue May 31 23:49:09.794761 2022] [wsgi:error] [pid 11244] [client 127.0.0.1:42920] Target WSGI script not found or unable to stat: /home/freddy/www/multitenant/wsgi.py
[Tue May 31 23:49:10.287612 2022] [wsgi:error] [pid 11244] [client 127.0.0.1:42920] Target WSGI script not found or unable to stat: /home/freddy/www/multitenant/wsgi.py
[Tue May 31 22:50:23.231689 2022] [wsgi:error] [pid 11483] [remote 127.0.0.1:42924] Invalid HTTP_HOST header: 'multi.mydev'. You may need to add 'multi.mydev' to ALLOWED_HOSTS.
[Tue May 31 22:50:23.249811 2022] [wsgi:error] [pid 11483] [remote 127.0.0.1:42924] Bad Request: /
Exception ignored in: <function Local.__del__ at 0x7fd6ecc1ce50>
Traceback (most recent call last):
  File "/home/freddy/www/multitenant/venv/lib/python3.8/site-packages/asgiref/local.py", line 94, in __del__
NameError: name 'TypeError' is not defined
Exception ignored in: <function Local.__del__ at 0x7fd6ecc1ce50>
Traceback (most recent call last):
  File "/home/freddy/www/multitenant/venv/lib/python3.8/site-packages/asgiref/local.py", line 94, in __del__
NameError: name 'TypeError' is not defined
[Tue May 31 22:50:53.941570 2022] [wsgi:error] [pid 11732] [remote 127.0.0.1:42928] Internal Server Error: /
[Tue May 31 22:50:53.941613 2022] [wsgi:error] [pid 11732] [remote 127.0.0.1:42928] Traceback (most recent call last):
[Tue May 31 22:50:53.941626 2022] [wsgi:error] [pid 11732] [remote 127.0.0.1:42928]   File "/home/freddy/www/multitenant/venv/lib/python3.8/site-packages/django/db/backends/base/base.py", line 244, in ensure_connection
[Tue May 31 22:50:53.941628 2022] [wsgi:error] [pid 11732] [remote 127.0.0.1:42928]     self.connect()
[Tue May 31 22:50:53.941630 2022] [wsgi:error] [pid 11732] [remote 127.0.0.1:42928]   File "/home/freddy/www/multitenant/venv/lib/python3.8/site-packages/django/utils/asyncio.py", line 26, in inner
[Tue May 31 22:50:53.941632 2022] [wsgi:error] [pid 11732] [remote 127.0.0.1:42928]     return func(*args, **kwargs)
[Tue May 31 22:50:53.941634 2022] [wsgi:error] [pid 11732] [remote 127.0.0.1:42928]   File "/home/freddy/www/multitenant/venv/lib/python3.8/site-packages/django/db/backends/base/base.py", line 225, in connect
[Tue May 31 22:50:53.941636 2022] [wsgi:error] [pid 11732] [remote 127.0.0.1:42928]     self.connection = self.get_new_connection(conn_params)
[Tue May 31 22:50:53.941638 2022] [wsgi:error] [pid 11732] [remote 127.0.0.1:42928]   File "/home/freddy/www/multitenant/venv/lib/python3.8/site-packages/django/utils/asyncio.py", line 26, in inner
[Tue May 31 22:50:53.941640 2022] [wsgi:error] [pid 11732] [remote 127.0.0.1:42928]     return func(*args, **kwargs)
[Tue May 31 22:50:53.941642 2022] [wsgi:error] [pid 11732] [remote 127.0.0.1:42928]   File "/home/freddy/www/multitenant/venv/lib/python3.8/site-packages/django/db/backends/postgresql/base.py", line 203, in get_new_connection
[Tue May 31 22:50:53.941644 2022] [wsgi:error] [pid 11732] [remote 127.0.0.1:42928]     connection = Database.connect(**conn_params)
[Tue May 31 22:50:53.941647 2022] [wsgi:error] [pid 11732] [remote 127.0.0.1:42928]   File "/home/freddy/www/multitenant/venv/lib/python3.8/site-packages/psycopg2/__init__.py", line 122, in connect
[Tue May 31 22:50:53.941649 2022] [wsgi:error] [pid 11732] [remote 127.0.0.1:42928]     conn = _connect(dsn, connection_factory=connection_factory, **kwasync)
[Tue May 31 22:50:53.941652 2022] [wsgi:error] [pid 11732] [remote 127.0.0.1:42928] psycopg2.OperationalError: connection to server at "127.0.0.1", port 5432 failed: Connection refused
[Tue May 31 22:50:53.941654 2022] [wsgi:error] [pid 11732] [remote 127.0.0.1:42928] \tIs the server running on that host and accepting TCP/IP connections?
[Tue May 31 22:50:53.941657 2022] [wsgi:error] [pid 11732] [remote 127.0.0.1:42928] 
[Tue May 31 22:50:53.941659 2022] [wsgi:error] [pid 11732] [remote 127.0.0.1:42928] 
[Tue May 31 22:50:53.941661 2022] [wsgi:error] [pid 11732] [remote 127.0.0.1:42928] The above exception was the direct cause of the following exception:
[Tue May 31 22:50:53.941663 2022] [wsgi:error] [pid 11732] [remote 127.0.0.1:42928] 
[Tue May 31 22:50:53.941665 2022] [wsgi:error] [pid 11732] [remote 127.0.0.1:42928] Traceback (most recent call last):
[Tue May 31 22:50:53.941667 2022] [wsgi:error] [pid 11732] [remote 127.0.0.1:42928]   File "/home/freddy/www/multitenant/venv/lib/python3.8/site-packages/django/core/handlers/exception.py", line 55, in inner
[Tue May 31 22:50:53.941670 2022] [wsgi:error] [pid 11732] [remote 127.0.0.1:42928]     response = get_response(request)
[Tue May 31 22:50:53.941672 2022] [wsgi:error] [pid 11732] [remote 127.0.0.1:42928]   File "/home/freddy/www/multitenant/venv/lib/python3.8/site-packages/django/utils/deprecation.py", line 133, in __call__
[Tue May 31 22:50:53.941674 2022] [wsgi:error] [pid 11732] [remote 127.0.0.1:42928]     response = self.process_request(request)
[Tue May 31 22:50:53.941676 2022] [wsgi:error] [pid 11732] [remote 127.0.0.1:42928]   File "/home/freddy/www/multitenant/venv/lib/python3.8/site-packages/django_tenants/middleware/main.py", line 39, in process_request
[Tue May 31 22:50:53.941679 2022] [wsgi:error] [pid 11732] [remote 127.0.0.1:42928]     tenant = self.get_tenant(domain_model, hostname)
[Tue May 31 22:50:53.941681 2022] [wsgi:error] [pid 11732] [remote 127.0.0.1:42928]   File "/home/freddy/www/multitenant/venv/lib/python3.8/site-packages/django_tenants/middleware/main.py", line 27, in get_tenant
[Tue May 31 22:50:53.941685 2022] [wsgi:error] [pid 11732] [remote 127.0.0.1:42928]     domain = domain_model.objects.select_related('tenant').get(domain=hostname)
[Tue May 31 22:50:53.941687 2022] [wsgi:error] [pid 11732] [remote 127.0.0.1:42928]   File "/home/freddy/www/multitenant/venv/lib/python3.8/site-packages/django/db/models/query.py", line 492, in get
[Tue May 31 22:50:53.941689 2022] [wsgi:error] [pid 11732] [remote 127.0.0.1:42928]     num = len(clone)
[Tue May 31 22:50:53.941691 2022] [wsgi:error] [pid 11732] [remote 127.0.0.1:42928]   File "/home/freddy/www/multitenant/venv/lib/python3.8/site-packages/django/db/models/query.py", line 302, in __len__
[Tue May 31 22:50:53.941701 2022] [wsgi:error] [pid 11732] [remote 127.0.0.1:42928]     self._fetch_all()
[Tue May 31 22:50:53.941704 2022] [wsgi:error] [pid 11732] [remote 127.0.0.1:42928]   File "/home/freddy/www/multitenant/venv/lib/python3.8/site-packages/django/db/models/query.py", line 1507, in _fetch_all
[Tue May 31 22:50:53.941706 2022] [wsgi:error] [pid 11732] [remote 127.0.0.1:42928]     self._result_cache = list(self._iterable_class(self))
[Tue May 31 22:50:53.941709 2022] [wsgi:error] [pid 11732] [remote 127.0.0.1:42928]   File "/home/freddy/www/multitenant/venv/lib/python3.8/site-packages/django/db/models/query.py", line 57, in __iter__
[Tue May 31 22:50:53.941712 2022] [wsgi:error] [pid 11732] [remote 127.0.0.1:42928]     results = compiler.execute_sql(
[Tue May 31 22:50:53.941715 2022] [wsgi:error] [pid 11732] [remote 127.0.0.1:42928]   File "/home/freddy/www/multitenant/venv/lib/python3.8/site-packages/django/db/models/sql/compiler.py", line 1359, in execute_sql
[Tue May 31 22:50:53.941717 2022] [wsgi:error] [pid 11732] [remote 127.0.0.1:42928]     cursor = self.connection.cursor()
[Tue May 31 22:50:53.941720 2022] [wsgi:error] [pid 11732] [remote 127.0.0.1:42928]   File "/home/freddy/www/multitenant/venv/lib/python3.8/site-packages/django/utils/asyncio.py", line 26, in inner
[Tue May 31 22:50:53.941722 2022] [wsgi:error] [pid 11732] [remote 127.0.0.1:42928]     return func(*args, **kwargs)
[Tue May 31 22:50:53.941724 2022] [wsgi:error] [pid 11732] [remote 127.0.0.1:42928]   File "/home/freddy/www/multitenant/venv/lib/python3.8/site-packages/django/db/backends/base/base.py", line 284, in cursor
[Tue May 31 22:50:53.941726 2022] [wsgi:error] [pid 11732] [remote 127.0.0.1:42928]     return self._cursor()
[Tue May 31 22:50:53.941728 2022] [wsgi:error] [pid 11732] [remote 127.0.0.1:42928]   File "/home/freddy/www/multitenant/venv/lib/python3.8/site-packages/django_tenants/postgresql_backend/base.py", line 122, in _cursor
[Tue May 31 22:50:53.941730 2022] [wsgi:error] [pid 11732] [remote 127.0.0.1:42928]     cursor = super()._cursor()
[Tue May 31 22:50:53.941732 2022] [wsgi:error] [pid 11732] [remote 127.0.0.1:42928]   File "/home/freddy/www/multitenant/venv/lib/python3.8/site-packages/django/db/backends/base/base.py", line 260, in _cursor
[Tue May 31 22:50:53.941733 2022] [wsgi:error] [pid 11732] [remote 127.0.0.1:42928]     self.ensure_connection()
[Tue May 31 22:50:53.941735 2022] [wsgi:error] [pid 11732] [remote 127.0.0.1:42928]   File "/home/freddy/www/multitenant/venv/lib/python3.8/site-packages/django/utils/asyncio.py", line 26, in inner
[Tue May 31 22:50:53.941738 2022] [wsgi:error] [pid 11732] [remote 127.0.0.1:42928]     return func(*args, **kwargs)
[Tue May 31 22:50:53.941740 2022] [wsgi:error] [pid 11732] [remote 127.0.0.1:42928]   File "/home/freddy/www/multitenant/venv/lib/python3.8/site-packages/django/db/backends/base/base.py", line 244, in ensure_connection
[Tue May 31 22:50:53.941741 2022] [wsgi:error] [pid 11732] [remote 127.0.0.1:42928]     self.connect()
[Tue May 31 22:50:53.941743 2022] [wsgi:error] [pid 11732] [remote 127.0.0.1:42928]   File "/home/freddy/www/multitenant/venv/lib/python3.8/site-packages/django/db/utils.py", line 91, in __exit__
[Tue May 31 22:50:53.941745 2022] [wsgi:error] [pid 11732] [remote 127.0.0.1:42928]     raise dj_exc_value.with_traceback(traceback) from exc_value
[Tue May 31 22:50:53.941749 2022] [wsgi:error] [pid 11732] [remote 127.0.0.1:42928]   File "/home/freddy/www/multitenant/venv/lib/python3.8/site-packages/django/db/backends/base/base.py", line 244, in ensure_connection
[Tue May 31 22:50:53.941751 2022] [wsgi:error] [pid 11732] [remote 127.0.0.1:42928]     self.connect()
[Tue May 31 22:50:53.941753 2022] [wsgi:error] [pid 11732] [remote 127.0.0.1:42928]   File "/home/freddy/www/multitenant/venv/lib/python3.8/site-packages/django/utils/asyncio.py", line 26, in inner
[Tue May 31 22:50:53.941755 2022] [wsgi:error] [pid 11732] [remote 127.0.0.1:42928]     return func(*args, **kwargs)
[Tue May 31 22:50:53.941757 2022] [wsgi:error] [pid 11732] [remote 127.0.0.1:42928]   File "/home/freddy/www/multitenant/venv/lib/python3.8/site-packages/django/db/backends/base/base.py", line 225, in connect
[Tue May 31 22:50:53.941759 2022] [wsgi:error] [pid 11732] [remote 127.0.0.1:42928]     self.connection = self.get_new_connection(conn_params)
[Tue May 31 22:50:53.941761 2022] [wsgi:error] [pid 11732] [remote 127.0.0.1:42928]   File "/home/freddy/www/multitenant/venv/lib/python3.8/site-packages/django/utils/asyncio.py", line 26, in inner
[Tue May 31 22:50:53.941763 2022] [wsgi:error] [pid 11732] [remote 127.0.0.1:42928]     return func(*args, **kwargs)
[Tue May 31 22:50:53.941765 2022] [wsgi:error] [pid 11732] [remote 127.0.0.1:42928]   File "/home/freddy/www/multitenant/venv/lib/python3.8/site-packages/django/db/backends/postgresql/base.py", line 203, in get_new_connection
[Tue May 31 22:50:53.941767 2022] [wsgi:error] [pid 11732] [remote 127.0.0.1:42928]     connection = Database.connect(**conn_params)
[Tue May 31 22:50:53.941769 2022] [wsgi:error] [pid 11732] [remote 127.0.0.1:42928]   File "/home/freddy/www/multitenant/venv/lib/python3.8/site-packages/psycopg2/__init__.py", line 122, in connect
[Tue May 31 22:50:53.941771 2022] [wsgi:error] [pid 11732] [remote 127.0.0.1:42928]     conn = _connect(dsn, connection_factory=connection_factory, **kwasync)
[Tue May 31 22:50:53.941772 2022] [wsgi:error] [pid 11732] [remote 127.0.0.1:42928] django.db.utils.OperationalError: connection to server at "127.0.0.1", port 5432 failed: Connection refused
[Tue May 31 22:50:53.941775 2022] [wsgi:error] [pid 11732] [remote 127.0.0.1:42928] \tIs the server running on that host and accepting TCP/IP connections?
[Tue May 31 22:50:53.941777 2022] [wsgi:error] [pid 11732] [remote 127.0.0.1:42928] 
[Tue May 31 22:51:06.001017 2022] [wsgi:error] [pid 11732] [remote 127.0.0.1:42930] Not Found: /
Exception ignored in: <function Local.__del__ at 0x7f84dc0ebe50>
Traceback (most recent call last):
  File "/home/freddy/www/multitenant/venv/lib/python3.8/site-packages/asgiref/local.py", line 94, in __del__
NameError: name 'TypeError' is not defined
Exception ignored in: <function Local.__del__ at 0x7f84dc0ebe50>
Traceback (most recent call last):
  File "/home/freddy/www/multitenant/venv/lib/python3.8/site-packages/asgiref/local.py", line 94, in __del__
NameError: name 'TypeError' is not defined
Exception ignored in: <function Local.__del__ at 0x7fc54ba15e50>
Traceback (most recent call last):
  File "/home/freddy/www/multitenant/venv/lib/python3.8/site-packages/asgiref/local.py", line 94, in __del__
NameError: name 'TypeError' is not defined
Exception ignored in: <function Local.__del__ at 0x7fc54ba15e50>
Traceback (most recent call last):
  File "/home/freddy/www/multitenant/venv/lib/python3.8/site-packages/asgiref/local.py", line 94, in __del__
NameError: name 'TypeError' is not defined
[Tue May 31 22:52:47.204584 2022] [wsgi:error] [pid 12376] [remote 127.0.0.1:42956] Not Found: /
[Tue May 31 22:55:16.959905 2022] [wsgi:error] [pid 12376] [remote 127.0.0.1:42980] Not Found: /favicon.ico
Exception ignored in: <function Local.__del__ at 0x7fe929171e50>
Traceback (most recent call last):
  File "/home/freddy/www/multitenant/venv/lib/python3.8/site-packages/asgiref/local.py", line 94, in __del__
NameError: name 'TypeError' is not defined
Exception ignored in: <function Local.__del__ at 0x7fe929171e50>
Traceback (most recent call last):
  File "/home/freddy/www/multitenant/venv/lib/python3.8/site-packages/asgiref/local.py", line 94, in __del__
NameError: name 'TypeError' is not defined
Exception ignored in: <function Local.__del__ at 0x7fce62f8be50>
Traceback (most recent call last):
  File "/home/freddy/www/multitenant/venv/lib/python3.8/site-packages/asgiref/local.py", line 94, in __del__
NameError: name 'TypeError' is not defined
Exception ignored in: <function Local.__del__ at 0x7fce62f8be50>
Traceback (most recent call last):
  File "/home/freddy/www/multitenant/venv/lib/python3.8/site-packages/asgiref/local.py", line 94, in __del__
NameError: name 'TypeError' is not defined
Exception ignored in: <function Local.__del__ at 0x7f62a7cace50>
Traceback (most recent call last):
  File "/home/freddy/www/multitenant/venv/lib/python3.8/site-packages/asgiref/local.py", line 94, in __del__
NameError: name 'TypeError' is not defined
Exception ignored in: <function Local.__del__ at 0x7f62a7cace50>
Traceback (most recent call last):
  File "/home/freddy/www/multitenant/venv/lib/python3.8/site-packages/asgiref/local.py", line 94, in __del__
NameError: name 'TypeError' is not defined
Exception ignored in: <function Local.__del__ at 0x7f7a53b88e50>
Traceback (most recent call last):
  File "/home/freddy/www/multitenant/venv/lib/python3.8/site-packages/asgiref/local.py", line 94, in __del__
NameError: name 'TypeError' is not defined
Exception ignored in: <function Local.__del__ at 0x7f7a53b88e50>
Traceback (most recent call last):
  File "/home/freddy/www/multitenant/venv/lib/python3.8/site-packages/asgiref/local.py", line 94, in __del__
NameError: name 'TypeError' is not defined
[Tue May 31 23:12:21.876879 2022] [wsgi:error] [pid 17975] [remote 127.0.0.1:43072] Invalid HTTP_HOST header: 'toto.multi.mydev'. You may need to add 'toto.multi.mydev' to ALLOWED_HOSTS.
[Tue May 31 23:12:21.892944 2022] [wsgi:error] [pid 17975] [remote 127.0.0.1:43072] Bad Request: /admin/login/
Exception ignored in: <function Local.__del__ at 0x7fa368872e50>
Traceback (most recent call last):
  File "/home/freddy/www/multitenant/venv/lib/python3.8/site-packages/asgiref/local.py", line 94, in __del__
NameError: name 'TypeError' is not defined
Exception ignored in: <function Local.__del__ at 0x7fa368872e50>
Traceback (most recent call last):
  File "/home/freddy/www/multitenant/venv/lib/python3.8/site-packages/asgiref/local.py", line 94, in __del__
NameError: name 'TypeError' is not defined
[Tue May 31 23:12:51.804750 2022] [wsgi:error] [pid 18242] [remote 127.0.0.1:43076] Invalid HTTP_HOST header: 'toto.multi.mydev'. You may need to add 'toto.multi.mydev' to ALLOWED_HOSTS.
[Tue May 31 23:12:51.821951 2022] [wsgi:error] [pid 18242] [remote 127.0.0.1:43076] Bad Request: /admin/login/
[Tue May 31 23:13:08.772425 2022] [wsgi:error] [pid 18242] [remote 127.0.0.1:43078] Invalid HTTP_HOST header: 'toto.multi.mydev'. You may need to add 'toto.multi.mydev' to ALLOWED_HOSTS.
[Tue May 31 23:13:08.787224 2022] [wsgi:error] [pid 18242] [remote 127.0.0.1:43078] Bad Request: /admin/login/
Exception ignored in: <function Local.__del__ at 0x7f6c66ea3e50>
Traceback (most recent call last):
  File "/home/freddy/www/multitenant/venv/lib/python3.8/site-packages/asgiref/local.py", line 94, in __del__
NameError: name 'TypeError' is not defined
Exception ignored in: <function Local.__del__ at 0x7f6c66ea3e50>
Traceback (most recent call last):
  File "/home/freddy/www/multitenant/venv/lib/python3.8/site-packages/asgiref/local.py", line 94, in __del__
NameError: name 'TypeError' is not defined
[Tue May 31 23:16:48.197132 2022] [wsgi:error] [pid 18658] [remote 127.0.0.1:43094] Internal Server Error: /demands/
[Tue May 31 23:16:48.197183 2022] [wsgi:error] [pid 18658] [remote 127.0.0.1:43094] Traceback (most recent call last):
[Tue May 31 23:16:48.197186 2022] [wsgi:error] [pid 18658] [remote 127.0.0.1:43094]   File "/home/freddy/www/multitenant/venv/lib/python3.8/site-packages/django/core/handlers/exception.py", line 55, in inner
[Tue May 31 23:16:48.197187 2022] [wsgi:error] [pid 18658] [remote 127.0.0.1:43094]     response = get_response(request)
[Tue May 31 23:16:48.197195 2022] [wsgi:error] [pid 18658] [remote 127.0.0.1:43094]   File "/home/freddy/www/multitenant/venv/lib/python3.8/site-packages/django/core/handlers/base.py", line 197, in _get_response
[Tue May 31 23:16:48.197196 2022] [wsgi:error] [pid 18658] [remote 127.0.0.1:43094]     response = wrapped_callback(request, *callback_args, **callback_kwargs)
[Tue May 31 23:16:48.197198 2022] [wsgi:error] [pid 18658] [remote 127.0.0.1:43094]   File "/home/freddy/www/multitenant/venv/lib/python3.8/site-packages/django/views/decorators/csrf.py", line 54, in wrapped_view
[Tue May 31 23:16:48.197200 2022] [wsgi:error] [pid 18658] [remote 127.0.0.1:43094]     return view_func(*args, **kwargs)
[Tue May 31 23:16:48.197201 2022] [wsgi:error] [pid 18658] [remote 127.0.0.1:43094]   File "/home/freddy/www/multitenant/venv/lib/python3.8/site-packages/django/views/generic/base.py", line 84, in view
[Tue May 31 23:16:48.197203 2022] [wsgi:error] [pid 18658] [remote 127.0.0.1:43094]     return self.dispatch(request, *args, **kwargs)
[Tue May 31 23:16:48.197204 2022] [wsgi:error] [pid 18658] [remote 127.0.0.1:43094]   File "/home/freddy/www/multitenant/venv/lib/python3.8/site-packages/rest_framework/views.py", line 509, in dispatch
[Tue May 31 23:16:48.197206 2022] [wsgi:error] [pid 18658] [remote 127.0.0.1:43094]     response = self.handle_exception(exc)
[Tue May 31 23:16:48.197207 2022] [wsgi:error] [pid 18658] [remote 127.0.0.1:43094]   File "/home/freddy/www/multitenant/venv/lib/python3.8/site-packages/rest_framework/views.py", line 469, in handle_exception
[Tue May 31 23:16:48.197209 2022] [wsgi:error] [pid 18658] [remote 127.0.0.1:43094]     self.raise_uncaught_exception(exc)
[Tue May 31 23:16:48.197210 2022] [wsgi:error] [pid 18658] [remote 127.0.0.1:43094]   File "/home/freddy/www/multitenant/venv/lib/python3.8/site-packages/rest_framework/views.py", line 480, in raise_uncaught_exception
[Tue May 31 23:16:48.197212 2022] [wsgi:error] [pid 18658] [remote 127.0.0.1:43094]     raise exc
[Tue May 31 23:16:48.197213 2022] [wsgi:error] [pid 18658] [remote 127.0.0.1:43094]   File "/home/freddy/www/multitenant/venv/lib/python3.8/site-packages/rest_framework/views.py", line 506, in dispatch
[Tue May 31 23:16:48.197215 2022] [wsgi:error] [pid 18658] [remote 127.0.0.1:43094]     response = handler(request, *args, **kwargs)
[Tue May 31 23:16:48.197218 2022] [wsgi:error] [pid 18658] [remote 127.0.0.1:43094]   File "/home/freddy/www/multitenant/demands/views.py", line 8, in get
[Tue May 31 23:16:48.197219 2022] [wsgi:error] [pid 18658] [remote 127.0.0.1:43094]     class ListCreateDemand(generics.ListCreateAPIView):
[Tue May 31 23:16:48.197221 2022] [wsgi:error] [pid 18658] [remote 127.0.0.1:43094] NameError: name 'Demand' is not defined
[Tue May 31 23:17:11.528860 2022] [wsgi:error] [pid 18658] [remote 127.0.0.1:43096] Internal Server Error: /demands/
[Tue May 31 23:17:11.528896 2022] [wsgi:error] [pid 18658] [remote 127.0.0.1:43096] Traceback (most recent call last):
[Tue May 31 23:17:11.528899 2022] [wsgi:error] [pid 18658] [remote 127.0.0.1:43096]   File "/home/freddy/www/multitenant/venv/lib/python3.8/site-packages/django/core/handlers/exception.py", line 55, in inner
[Tue May 31 23:17:11.528902 2022] [wsgi:error] [pid 18658] [remote 127.0.0.1:43096]     response = get_response(request)
[Tue May 31 23:17:11.528904 2022] [wsgi:error] [pid 18658] [remote 127.0.0.1:43096]   File "/home/freddy/www/multitenant/venv/lib/python3.8/site-packages/django/core/handlers/base.py", line 197, in _get_response
[Tue May 31 23:17:11.528907 2022] [wsgi:error] [pid 18658] [remote 127.0.0.1:43096]     response = wrapped_callback(request, *callback_args, **callback_kwargs)
[Tue May 31 23:17:11.528909 2022] [wsgi:error] [pid 18658] [remote 127.0.0.1:43096]   File "/home/freddy/www/multitenant/venv/lib/python3.8/site-packages/django/views/decorators/csrf.py", line 54, in wrapped_view
[Tue May 31 23:17:11.528912 2022] [wsgi:error] [pid 18658] [remote 127.0.0.1:43096]     return view_func(*args, **kwargs)
[Tue May 31 23:17:11.528938 2022] [wsgi:error] [pid 18658] [remote 127.0.0.1:43096]   File "/home/freddy/www/multitenant/venv/lib/python3.8/site-packages/django/views/generic/base.py", line 84, in view
[Tue May 31 23:17:11.528941 2022] [wsgi:error] [pid 18658] [remote 127.0.0.1:43096]     return self.dispatch(request, *args, **kwargs)
[Tue May 31 23:17:11.528943 2022] [wsgi:error] [pid 18658] [remote 127.0.0.1:43096]   File "/home/freddy/www/multitenant/venv/lib/python3.8/site-packages/rest_framework/views.py", line 509, in dispatch
[Tue May 31 23:17:11.528946 2022] [wsgi:error] [pid 18658] [remote 127.0.0.1:43096]     response = self.handle_exception(exc)
[Tue May 31 23:17:11.528948 2022] [wsgi:error] [pid 18658] [remote 127.0.0.1:43096]   File "/home/freddy/www/multitenant/venv/lib/python3.8/site-packages/rest_framework/views.py", line 469, in handle_exception
[Tue May 31 23:17:11.528950 2022] [wsgi:error] [pid 18658] [remote 127.0.0.1:43096]     self.raise_uncaught_exception(exc)
[Tue May 31 23:17:11.528953 2022] [wsgi:error] [pid 18658] [remote 127.0.0.1:43096]   File "/home/freddy/www/multitenant/venv/lib/python3.8/site-packages/rest_framework/views.py", line 480, in raise_uncaught_exception
[Tue May 31 23:17:11.528955 2022] [wsgi:error] [pid 18658] [remote 127.0.0.1:43096]     raise exc
[Tue May 31 23:17:11.528958 2022] [wsgi:error] [pid 18658] [remote 127.0.0.1:43096]   File "/home/freddy/www/multitenant/venv/lib/python3.8/site-packages/rest_framework/views.py", line 506, in dispatch
[Tue May 31 23:17:11.528960 2022] [wsgi:error] [pid 18658] [remote 127.0.0.1:43096]     response = handler(request, *args, **kwargs)
[Tue May 31 23:17:11.528962 2022] [wsgi:error] [pid 18658] [remote 127.0.0.1:43096]   File "/home/freddy/www/multitenant/demands/views.py", line 8, in get
[Tue May 31 23:17:11.528965 2022] [wsgi:error] [pid 18658] [remote 127.0.0.1:43096]     class ListCreateDemand(generics.ListCreateAPIView):
[Tue May 31 23:17:11.528967 2022] [wsgi:error] [pid 18658] [remote 127.0.0.1:43096] NameError: name 'Demand' is not defined
[Tue May 31 23:17:12.234200 2022] [wsgi:error] [pid 18658] [remote 127.0.0.1:43098] Internal Server Error: /demands/
[Tue May 31 23:17:12.234226 2022] [wsgi:error] [pid 18658] [remote 127.0.0.1:43098] Traceback (most recent call last):
[Tue May 31 23:17:12.234229 2022] [wsgi:error] [pid 18658] [remote 127.0.0.1:43098]   File "/home/freddy/www/multitenant/venv/lib/python3.8/site-packages/django/core/handlers/exception.py", line 55, in inner
[Tue May 31 23:17:12.234231 2022] [wsgi:error] [pid 18658] [remote 127.0.0.1:43098]     response = get_response(request)
[Tue May 31 23:17:12.234232 2022] [wsgi:error] [pid 18658] [remote 127.0.0.1:43098]   File "/home/freddy/www/multitenant/venv/lib/python3.8/site-packages/django/core/handlers/base.py", line 197, in _get_response
[Tue May 31 23:17:12.234234 2022] [wsgi:error] [pid 18658] [remote 127.0.0.1:43098]     response = wrapped_callback(request, *callback_args, **callback_kwargs)
[Tue May 31 23:17:12.234236 2022] [wsgi:error] [pid 18658] [remote 127.0.0.1:43098]   File "/home/freddy/www/multitenant/venv/lib/python3.8/site-packages/django/views/decorators/csrf.py", line 54, in wrapped_view
[Tue May 31 23:17:12.234237 2022] [wsgi:error] [pid 18658] [remote 127.0.0.1:43098]     return view_func(*args, **kwargs)
[Tue May 31 23:17:12.234239 2022] [wsgi:error] [pid 18658] [remote 127.0.0.1:43098]   File "/home/freddy/www/multitenant/venv/lib/python3.8/site-packages/django/views/generic/base.py", line 84, in view
[Tue May 31 23:17:12.234240 2022] [wsgi:error] [pid 18658] [remote 127.0.0.1:43098]     return self.dispatch(request, *args, **kwargs)
[Tue May 31 23:17:12.234242 2022] [wsgi:error] [pid 18658] [remote 127.0.0.1:43098]   File "/home/freddy/www/multitenant/venv/lib/python3.8/site-packages/rest_framework/views.py", line 509, in dispatch
[Tue May 31 23:17:12.234243 2022] [wsgi:error] [pid 18658] [remote 127.0.0.1:43098]     response = self.handle_exception(exc)
[Tue May 31 23:17:12.234245 2022] [wsgi:error] [pid 18658] [remote 127.0.0.1:43098]   File "/home/freddy/www/multitenant/venv/lib/python3.8/site-packages/rest_framework/views.py", line 469, in handle_exception
[Tue May 31 23:17:12.234254 2022] [wsgi:error] [pid 18658] [remote 127.0.0.1:43098]     self.raise_uncaught_exception(exc)
[Tue May 31 23:17:12.234255 2022] [wsgi:error] [pid 18658] [remote 127.0.0.1:43098]   File "/home/freddy/www/multitenant/venv/lib/python3.8/site-packages/rest_framework/views.py", line 480, in raise_uncaught_exception
[Tue May 31 23:17:12.234257 2022] [wsgi:error] [pid 18658] [remote 127.0.0.1:43098]     raise exc
[Tue May 31 23:17:12.234258 2022] [wsgi:error] [pid 18658] [remote 127.0.0.1:43098]   File "/home/freddy/www/multitenant/venv/lib/python3.8/site-packages/rest_framework/views.py", line 506, in dispatch
[Tue May 31 23:17:12.234260 2022] [wsgi:error] [pid 18658] [remote 127.0.0.1:43098]     response = handler(request, *args, **kwargs)
[Tue May 31 23:17:12.234261 2022] [wsgi:error] [pid 18658] [remote 127.0.0.1:43098]   File "/home/freddy/www/multitenant/demands/views.py", line 8, in get
[Tue May 31 23:17:12.234263 2022] [wsgi:error] [pid 18658] [remote 127.0.0.1:43098]     class ListCreateDemand(generics.ListCreateAPIView):
[Tue May 31 23:17:12.234264 2022] [wsgi:error] [pid 18658] [remote 127.0.0.1:43098] NameError: name 'Demand' is not defined
[Tue May 31 23:17:12.906558 2022] [wsgi:error] [pid 18658] [remote 127.0.0.1:43100] Internal Server Error: /demands/
[Tue May 31 23:17:12.906583 2022] [wsgi:error] [pid 18658] [remote 127.0.0.1:43100] Traceback (most recent call last):
[Tue May 31 23:17:12.906585 2022] [wsgi:error] [pid 18658] [remote 127.0.0.1:43100]   File "/home/freddy/www/multitenant/venv/lib/python3.8/site-packages/django/core/handlers/exception.py", line 55, in inner
[Tue May 31 23:17:12.906587 2022] [wsgi:error] [pid 18658] [remote 127.0.0.1:43100]     response = get_response(request)
[Tue May 31 23:17:12.906588 2022] [wsgi:error] [pid 18658] [remote 127.0.0.1:43100]   File "/home/freddy/www/multitenant/venv/lib/python3.8/site-packages/django/core/handlers/base.py", line 197, in _get_response
[Tue May 31 23:17:12.906590 2022] [wsgi:error] [pid 18658] [remote 127.0.0.1:43100]     response = wrapped_callback(request, *callback_args, **callback_kwargs)
[Tue May 31 23:17:12.906591 2022] [wsgi:error] [pid 18658] [remote 127.0.0.1:43100]   File "/home/freddy/www/multitenant/venv/lib/python3.8/site-packages/django/views/decorators/csrf.py", line 54, in wrapped_view
[Tue May 31 23:17:12.906593 2022] [wsgi:error] [pid 18658] [remote 127.0.0.1:43100]     return view_func(*args, **kwargs)
[Tue May 31 23:17:12.906594 2022] [wsgi:error] [pid 18658] [remote 127.0.0.1:43100]   File "/home/freddy/www/multitenant/venv/lib/python3.8/site-packages/django/views/generic/base.py", line 84, in view
[Tue May 31 23:17:12.906596 2022] [wsgi:error] [pid 18658] [remote 127.0.0.1:43100]     return self.dispatch(request, *args, **kwargs)
[Tue May 31 23:17:12.906597 2022] [wsgi:error] [pid 18658] [remote 127.0.0.1:43100]   File "/home/freddy/www/multitenant/venv/lib/python3.8/site-packages/rest_framework/views.py", line 509, in dispatch
[Tue May 31 23:17:12.906599 2022] [wsgi:error] [pid 18658] [remote 127.0.0.1:43100]     response = self.handle_exception(exc)
[Tue May 31 23:17:12.906600 2022] [wsgi:error] [pid 18658] [remote 127.0.0.1:43100]   File "/home/freddy/www/multitenant/venv/lib/python3.8/site-packages/rest_framework/views.py", line 469, in handle_exception
[Tue May 31 23:17:12.906601 2022] [wsgi:error] [pid 18658] [remote 127.0.0.1:43100]     self.raise_uncaught_exception(exc)
[Tue May 31 23:17:12.906603 2022] [wsgi:error] [pid 18658] [remote 127.0.0.1:43100]   File "/home/freddy/www/multitenant/venv/lib/python3.8/site-packages/rest_framework/views.py", line 480, in raise_uncaught_exception
[Tue May 31 23:17:12.906604 2022] [wsgi:error] [pid 18658] [remote 127.0.0.1:43100]     raise exc
[Tue May 31 23:17:12.906606 2022] [wsgi:error] [pid 18658] [remote 127.0.0.1:43100]   File "/home/freddy/www/multitenant/venv/lib/python3.8/site-packages/rest_framework/views.py", line 506, in dispatch
[Tue May 31 23:17:12.906627 2022] [wsgi:error] [pid 18658] [remote 127.0.0.1:43100]     response = handler(request, *args, **kwargs)
[Tue May 31 23:17:12.906629 2022] [wsgi:error] [pid 18658] [remote 127.0.0.1:43100]   File "/home/freddy/www/multitenant/demands/views.py", line 8, in get
[Tue May 31 23:17:12.906630 2022] [wsgi:error] [pid 18658] [remote 127.0.0.1:43100]     class ListCreateDemand(generics.ListCreateAPIView):
[Tue May 31 23:17:12.906632 2022] [wsgi:error] [pid 18658] [remote 127.0.0.1:43100] NameError: name 'Demand' is not defined
[Tue May 31 23:18:49.875406 2022] [wsgi:error] [pid 18658] [remote 127.0.0.1:43104] Internal Server Error: /demands/
[Tue May 31 23:18:49.875434 2022] [wsgi:error] [pid 18658] [remote 127.0.0.1:43104] Traceback (most recent call last):
[Tue May 31 23:18:49.875436 2022] [wsgi:error] [pid 18658] [remote 127.0.0.1:43104]   File "/home/freddy/www/multitenant/venv/lib/python3.8/site-packages/django/core/handlers/exception.py", line 55, in inner
[Tue May 31 23:18:49.875438 2022] [wsgi:error] [pid 18658] [remote 127.0.0.1:43104]     response = get_response(request)
[Tue May 31 23:18:49.875439 2022] [wsgi:error] [pid 18658] [remote 127.0.0.1:43104]   File "/home/freddy/www/multitenant/venv/lib/python3.8/site-packages/django/core/handlers/base.py", line 197, in _get_response
[Tue May 31 23:18:49.875441 2022] [wsgi:error] [pid 18658] [remote 127.0.0.1:43104]     response = wrapped_callback(request, *callback_args, **callback_kwargs)
[Tue May 31 23:18:49.875443 2022] [wsgi:error] [pid 18658] [remote 127.0.0.1:43104]   File "/home/freddy/www/multitenant/venv/lib/python3.8/site-packages/django/views/decorators/csrf.py", line 54, in wrapped_view
[Tue May 31 23:18:49.875444 2022] [wsgi:error] [pid 18658] [remote 127.0.0.1:43104]     return view_func(*args, **kwargs)
[Tue May 31 23:18:49.875446 2022] [wsgi:error] [pid 18658] [remote 127.0.0.1:43104]   File "/home/freddy/www/multitenant/venv/lib/python3.8/site-packages/django/views/generic/base.py", line 84, in view
[Tue May 31 23:18:49.875448 2022] [wsgi:error] [pid 18658] [remote 127.0.0.1:43104]     return self.dispatch(request, *args, **kwargs)
[Tue May 31 23:18:49.875449 2022] [wsgi:error] [pid 18658] [remote 127.0.0.1:43104]   File "/home/freddy/www/multitenant/venv/lib/python3.8/site-packages/rest_framework/views.py", line 509, in dispatch
[Tue May 31 23:18:49.875451 2022] [wsgi:error] [pid 18658] [remote 127.0.0.1:43104]     response = self.handle_exception(exc)
[Tue May 31 23:18:49.875452 2022] [wsgi:error] [pid 18658] [remote 127.0.0.1:43104]   File "/home/freddy/www/multitenant/venv/lib/python3.8/site-packages/rest_framework/views.py", line 469, in handle_exception
[Tue May 31 23:18:49.875454 2022] [wsgi:error] [pid 18658] [remote 127.0.0.1:43104]     self.raise_uncaught_exception(exc)
[Tue May 31 23:18:49.875456 2022] [wsgi:error] [pid 18658] [remote 127.0.0.1:43104]   File "/home/freddy/www/multitenant/venv/lib/python3.8/site-packages/rest_framework/views.py", line 480, in raise_uncaught_exception
[Tue May 31 23:18:49.875457 2022] [wsgi:error] [pid 18658] [remote 127.0.0.1:43104]     raise exc
[Tue May 31 23:18:49.875459 2022] [wsgi:error] [pid 18658] [remote 127.0.0.1:43104]   File "/home/freddy/www/multitenant/venv/lib/python3.8/site-packages/rest_framework/views.py", line 506, in dispatch
[Tue May 31 23:18:49.875460 2022] [wsgi:error] [pid 18658] [remote 127.0.0.1:43104]     response = handler(request, *args, **kwargs)
[Tue May 31 23:18:49.875462 2022] [wsgi:error] [pid 18658] [remote 127.0.0.1:43104]   File "/home/freddy/www/multitenant/demands/views.py", line 8, in get
[Tue May 31 23:18:49.875463 2022] [wsgi:error] [pid 18658] [remote 127.0.0.1:43104]     class ListCreateDemand(generics.ListCreateAPIView):
[Tue May 31 23:18:49.875465 2022] [wsgi:error] [pid 18658] [remote 127.0.0.1:43104] NameError: name 'Demand' is not defined
Exception ignored in: <function Local.__del__ at 0x7f5ce1b73e50>
Traceback (most recent call last):
  File "/home/freddy/www/multitenant/venv/lib/python3.8/site-packages/asgiref/local.py", line 94, in __del__
NameError: name 'TypeError' is not defined
Exception ignored in: <function Local.__del__ at 0x7f5ce1b73e50>
Traceback (most recent call last):
  File "/home/freddy/www/multitenant/venv/lib/python3.8/site-packages/asgiref/local.py", line 94, in __del__
NameError: name 'TypeError' is not defined
[Tue May 31 23:20:06.615866 2022] [wsgi:error] [pid 20283] [remote 127.0.0.1:43108] Internal Server Error: /demands/
[Tue May 31 23:20:06.615900 2022] [wsgi:error] [pid 20283] [remote 127.0.0.1:43108] Traceback (most recent call last):
[Tue May 31 23:20:06.615903 2022] [wsgi:error] [pid 20283] [remote 127.0.0.1:43108]   File "/home/freddy/www/multitenant/venv/lib/python3.8/site-packages/django/core/handlers/exception.py", line 55, in inner
[Tue May 31 23:20:06.615905 2022] [wsgi:error] [pid 20283] [remote 127.0.0.1:43108]     response = get_response(request)
[Tue May 31 23:20:06.615906 2022] [wsgi:error] [pid 20283] [remote 127.0.0.1:43108]   File "/home/freddy/www/multitenant/venv/lib/python3.8/site-packages/django/core/handlers/base.py", line 197, in _get_response
[Tue May 31 23:20:06.615908 2022] [wsgi:error] [pid 20283] [remote 127.0.0.1:43108]     response = wrapped_callback(request, *callback_args, **callback_kwargs)
[Tue May 31 23:20:06.615910 2022] [wsgi:error] [pid 20283] [remote 127.0.0.1:43108]   File "/home/freddy/www/multitenant/venv/lib/python3.8/site-packages/django/views/decorators/csrf.py", line 54, in wrapped_view
[Tue May 31 23:20:06.615912 2022] [wsgi:error] [pid 20283] [remote 127.0.0.1:43108]     return view_func(*args, **kwargs)
[Tue May 31 23:20:06.615913 2022] [wsgi:error] [pid 20283] [remote 127.0.0.1:43108]   File "/home/freddy/www/multitenant/venv/lib/python3.8/site-packages/django/views/generic/base.py", line 84, in view
[Tue May 31 23:20:06.615915 2022] [wsgi:error] [pid 20283] [remote 127.0.0.1:43108]     return self.dispatch(request, *args, **kwargs)
[Tue May 31 23:20:06.615917 2022] [wsgi:error] [pid 20283] [remote 127.0.0.1:43108]   File "/home/freddy/www/multitenant/venv/lib/python3.8/site-packages/rest_framework/views.py", line 511, in dispatch
[Tue May 31 23:20:06.615919 2022] [wsgi:error] [pid 20283] [remote 127.0.0.1:43108]     self.response = self.finalize_response(request, response, *args, **kwargs)
[Tue May 31 23:20:06.615921 2022] [wsgi:error] [pid 20283] [remote 127.0.0.1:43108]   File "/home/freddy/www/multitenant/venv/lib/python3.8/site-packages/rest_framework/views.py", line 423, in finalize_response
[Tue May 31 23:20:06.615923 2022] [wsgi:error] [pid 20283] [remote 127.0.0.1:43108]     assert isinstance(response, HttpResponseBase), (
[Tue May 31 23:20:06.615925 2022] [wsgi:error] [pid 20283] [remote 127.0.0.1:43108] AssertionError: Expected a `Response`, `HttpResponse` or `HttpStreamingResponse` to be returned from the view, but received a `<class 'rest_framework.utils.serializer_helpers.ReturnList'>`
[Tue May 31 23:20:33.595447 2022] [wsgi:error] [pid 20283] [remote 127.0.0.1:43110] Internal Server Error: /demands/
[Tue May 31 23:20:33.595478 2022] [wsgi:error] [pid 20283] [remote 127.0.0.1:43110] Traceback (most recent call last):
[Tue May 31 23:20:33.595480 2022] [wsgi:error] [pid 20283] [remote 127.0.0.1:43110]   File "/home/freddy/www/multitenant/venv/lib/python3.8/site-packages/django/core/handlers/exception.py", line 55, in inner
[Tue May 31 23:20:33.595483 2022] [wsgi:error] [pid 20283] [remote 127.0.0.1:43110]     response = get_response(request)
[Tue May 31 23:20:33.595485 2022] [wsgi:error] [pid 20283] [remote 127.0.0.1:43110]   File "/home/freddy/www/multitenant/venv/lib/python3.8/site-packages/django/core/handlers/base.py", line 197, in _get_response
[Tue May 31 23:20:33.595487 2022] [wsgi:error] [pid 20283] [remote 127.0.0.1:43110]     response = wrapped_callback(request, *callback_args, **callback_kwargs)
[Tue May 31 23:20:33.595489 2022] [wsgi:error] [pid 20283] [remote 127.0.0.1:43110]   File "/home/freddy/www/multitenant/venv/lib/python3.8/site-packages/django/views/decorators/csrf.py", line 54, in wrapped_view
[Tue May 31 23:20:33.595491 2022] [wsgi:error] [pid 20283] [remote 127.0.0.1:43110]     return view_func(*args, **kwargs)
[Tue May 31 23:20:33.595499 2022] [wsgi:error] [pid 20283] [remote 127.0.0.1:43110]   File "/home/freddy/www/multitenant/venv/lib/python3.8/site-packages/django/views/generic/base.py", line 84, in view
[Tue May 31 23:20:33.595501 2022] [wsgi:error] [pid 20283] [remote 127.0.0.1:43110]     return self.dispatch(request, *args, **kwargs)
[Tue May 31 23:20:33.595503 2022] [wsgi:error] [pid 20283] [remote 127.0.0.1:43110]   File "/home/freddy/www/multitenant/venv/lib/python3.8/site-packages/rest_framework/views.py", line 511, in dispatch
[Tue May 31 23:20:33.595504 2022] [wsgi:error] [pid 20283] [remote 127.0.0.1:43110]     self.response = self.finalize_response(request, response, *args, **kwargs)
[Tue May 31 23:20:33.595506 2022] [wsgi:error] [pid 20283] [remote 127.0.0.1:43110]   File "/home/freddy/www/multitenant/venv/lib/python3.8/site-packages/rest_framework/views.py", line 423, in finalize_response
[Tue May 31 23:20:33.595507 2022] [wsgi:error] [pid 20283] [remote 127.0.0.1:43110]     assert isinstance(response, HttpResponseBase), (
[Tue May 31 23:20:33.595509 2022] [wsgi:error] [pid 20283] [remote 127.0.0.1:43110] AssertionError: Expected a `Response`, `HttpResponse` or `HttpStreamingResponse` to be returned from the view, but received a `<class 'rest_framework.utils.serializer_helpers.ReturnList'>`
[Tue May 31 23:20:34.659958 2022] [wsgi:error] [pid 20283] [remote 127.0.0.1:43112] Internal Server Error: /demands/
[Tue May 31 23:20:34.659984 2022] [wsgi:error] [pid 20283] [remote 127.0.0.1:43112] Traceback (most recent call last):
[Tue May 31 23:20:34.659987 2022] [wsgi:error] [pid 20283] [remote 127.0.0.1:43112]   File "/home/freddy/www/multitenant/venv/lib/python3.8/site-packages/django/core/handlers/exception.py", line 55, in inner
[Tue May 31 23:20:34.659989 2022] [wsgi:error] [pid 20283] [remote 127.0.0.1:43112]     response = get_response(request)
[Tue May 31 23:20:34.659991 2022] [wsgi:error] [pid 20283] [remote 127.0.0.1:43112]   File "/home/freddy/www/multitenant/venv/lib/python3.8/site-packages/django/core/handlers/base.py", line 197, in _get_response
[Tue May 31 23:20:34.659994 2022] [wsgi:error] [pid 20283] [remote 127.0.0.1:43112]     response = wrapped_callback(request, *callback_args, **callback_kwargs)
[Tue May 31 23:20:34.659996 2022] [wsgi:error] [pid 20283] [remote 127.0.0.1:43112]   File "/home/freddy/www/multitenant/venv/lib/python3.8/site-packages/django/views/decorators/csrf.py", line 54, in wrapped_view
[Tue May 31 23:20:34.659998 2022] [wsgi:error] [pid 20283] [remote 127.0.0.1:43112]     return view_func(*args, **kwargs)
[Tue May 31 23:20:34.660000 2022] [wsgi:error] [pid 20283] [remote 127.0.0.1:43112]   File "/home/freddy/www/multitenant/venv/lib/python3.8/site-packages/django/views/generic/base.py", line 84, in view
[Tue May 31 23:20:34.660002 2022] [wsgi:error] [pid 20283] [remote 127.0.0.1:43112]     return self.dispatch(request, *args, **kwargs)
[Tue May 31 23:20:34.660004 2022] [wsgi:error] [pid 20283] [remote 127.0.0.1:43112]   File "/home/freddy/www/multitenant/venv/lib/python3.8/site-packages/rest_framework/views.py", line 511, in dispatch
[Tue May 31 23:20:34.660007 2022] [wsgi:error] [pid 20283] [remote 127.0.0.1:43112]     self.response = self.finalize_response(request, response, *args, **kwargs)
[Tue May 31 23:20:34.660009 2022] [wsgi:error] [pid 20283] [remote 127.0.0.1:43112]   File "/home/freddy/www/multitenant/venv/lib/python3.8/site-packages/rest_framework/views.py", line 423, in finalize_response
[Tue May 31 23:20:34.660011 2022] [wsgi:error] [pid 20283] [remote 127.0.0.1:43112]     assert isinstance(response, HttpResponseBase), (
[Tue May 31 23:20:34.660014 2022] [wsgi:error] [pid 20283] [remote 127.0.0.1:43112] AssertionError: Expected a `Response`, `HttpResponse` or `HttpStreamingResponse` to be returned from the view, but received a `<class 'rest_framework.utils.serializer_helpers.ReturnList'>`
Exception ignored in: <function Local.__del__ at 0x7f0f5d095e50>
Traceback (most recent call last):
  File "/home/freddy/www/multitenant/venv/lib/python3.8/site-packages/asgiref/local.py", line 94, in __del__
NameError: name 'TypeError' is not defined
Exception ignored in: <function Local.__del__ at 0x7f0f5d095e50>
Traceback (most recent call last):
  File "/home/freddy/www/multitenant/venv/lib/python3.8/site-packages/asgiref/local.py", line 94, in __del__
NameError: name 'TypeError' is not defined
[Tue May 31 23:20:38.590275 2022] [wsgi:error] [pid 20610] [remote 127.0.0.1:43116] Internal Server Error: /demands/
[Tue May 31 23:20:38.590309 2022] [wsgi:error] [pid 20610] [remote 127.0.0.1:43116] Traceback (most recent call last):
[Tue May 31 23:20:38.590311 2022] [wsgi:error] [pid 20610] [remote 127.0.0.1:43116]   File "/home/freddy/www/multitenant/venv/lib/python3.8/site-packages/django/core/handlers/exception.py", line 55, in inner
[Tue May 31 23:20:38.590313 2022] [wsgi:error] [pid 20610] [remote 127.0.0.1:43116]     response = get_response(request)
[Tue May 31 23:20:38.590315 2022] [wsgi:error] [pid 20610] [remote 127.0.0.1:43116]   File "/home/freddy/www/multitenant/venv/lib/python3.8/site-packages/django/core/handlers/base.py", line 220, in _get_response
[Tue May 31 23:20:38.590317 2022] [wsgi:error] [pid 20610] [remote 127.0.0.1:43116]     response = response.render()
[Tue May 31 23:20:38.590318 2022] [wsgi:error] [pid 20610] [remote 127.0.0.1:43116]   File "/home/freddy/www/multitenant/venv/lib/python3.8/site-packages/django/template/response.py", line 114, in render
[Tue May 31 23:20:38.590320 2022] [wsgi:error] [pid 20610] [remote 127.0.0.1:43116]     self.content = self.rendered_content
[Tue May 31 23:20:38.590322 2022] [wsgi:error] [pid 20610] [remote 127.0.0.1:43116]   File "/home/freddy/www/multitenant/venv/lib/python3.8/site-packages/rest_framework/response.py", line 70, in rendered_content
[Tue May 31 23:20:38.590323 2022] [wsgi:error] [pid 20610] [remote 127.0.0.1:43116]     ret = renderer.render(self.data, accepted_media_type, context)
[Tue May 31 23:20:38.590325 2022] [wsgi:error] [pid 20610] [remote 127.0.0.1:43116]   File "/home/freddy/www/multitenant/venv/lib/python3.8/site-packages/rest_framework/renderers.py", line 724, in render
[Tue May 31 23:20:38.590327 2022] [wsgi:error] [pid 20610] [remote 127.0.0.1:43116]     context = self.get_context(data, accepted_media_type, renderer_context)
[Tue May 31 23:20:38.590328 2022] [wsgi:error] [pid 20610] [remote 127.0.0.1:43116]   File "/home/freddy/www/multitenant/venv/lib/python3.8/site-packages/rest_framework/renderers.py", line 655, in get_context
[Tue May 31 23:20:38.590330 2022] [wsgi:error] [pid 20610] [remote 127.0.0.1:43116]     raw_data_post_form = self.get_raw_data_form(data, view, 'POST', request)
[Tue May 31 23:20:38.590332 2022] [wsgi:error] [pid 20610] [remote 127.0.0.1:43116]   File "/home/freddy/www/multitenant/venv/lib/python3.8/site-packages/rest_framework/renderers.py", line 554, in get_raw_data_form
[Tue May 31 23:20:38.590333 2022] [wsgi:error] [pid 20610] [remote 127.0.0.1:43116]     serializer = view.get_serializer()
[Tue May 31 23:20:38.590335 2022] [wsgi:error] [pid 20610] [remote 127.0.0.1:43116]   File "/home/freddy/www/multitenant/venv/lib/python3.8/site-packages/rest_framework/generics.py", line 108, in get_serializer
[Tue May 31 23:20:38.590337 2022] [wsgi:error] [pid 20610] [remote 127.0.0.1:43116]     serializer_class = self.get_serializer_class()
[Tue May 31 23:20:38.590338 2022] [wsgi:error] [pid 20610] [remote 127.0.0.1:43116]   File "/home/freddy/www/multitenant/venv/lib/python3.8/site-packages/rest_framework/generics.py", line 122, in get_serializer_class
[Tue May 31 23:20:38.590340 2022] [wsgi:error] [pid 20610] [remote 127.0.0.1:43116]     assert self.serializer_class is not None, (
[Tue May 31 23:20:38.590353 2022] [wsgi:error] [pid 20610] [remote 127.0.0.1:43116] AssertionError: 'ListCreateDemand' should either include a `serializer_class` attribute, or override the `get_serializer_class()` method.
Exception ignored in: <function Local.__del__ at 0x7efc45a15e50>
Traceback (most recent call last):
  File "/home/freddy/www/multitenant/venv/lib/python3.8/site-packages/asgiref/local.py", line 94, in __del__
NameError: name 'TypeError' is not defined
Exception ignored in: <function Local.__del__ at 0x7efc45a15e50>
Traceback (most recent call last):
  File "/home/freddy/www/multitenant/venv/lib/python3.8/site-packages/asgiref/local.py", line 94, in __del__
NameError: name 'TypeError' is not defined
[Tue May 31 23:21:13.983553 2022] [wsgi:error] [pid 20911] [remote 127.0.0.1:43118] Internal Server Error: /demands/
[Tue May 31 23:21:13.983599 2022] [wsgi:error] [pid 20911] [remote 127.0.0.1:43118] Traceback (most recent call last):
[Tue May 31 23:21:13.983605 2022] [wsgi:error] [pid 20911] [remote 127.0.0.1:43118]   File "/home/freddy/www/multitenant/venv/lib/python3.8/site-packages/django/core/handlers/exception.py", line 55, in inner
[Tue May 31 23:21:13.983608 2022] [wsgi:error] [pid 20911] [remote 127.0.0.1:43118]     response = get_response(request)
[Tue May 31 23:21:13.983610 2022] [wsgi:error] [pid 20911] [remote 127.0.0.1:43118]   File "/home/freddy/www/multitenant/venv/lib/python3.8/site-packages/django/core/handlers/base.py", line 197, in _get_response
[Tue May 31 23:21:13.983613 2022] [wsgi:error] [pid 20911] [remote 127.0.0.1:43118]     response = wrapped_callback(request, *callback_args, **callback_kwargs)
[Tue May 31 23:21:13.983615 2022] [wsgi:error] [pid 20911] [remote 127.0.0.1:43118]   File "/home/freddy/www/multitenant/venv/lib/python3.8/site-packages/django/views/decorators/csrf.py", line 54, in wrapped_view
[Tue May 31 23:21:13.983618 2022] [wsgi:error] [pid 20911] [remote 127.0.0.1:43118]     return view_func(*args, **kwargs)
[Tue May 31 23:21:13.983620 2022] [wsgi:error] [pid 20911] [remote 127.0.0.1:43118]   File "/home/freddy/www/multitenant/venv/lib/python3.8/site-packages/django/views/generic/base.py", line 84, in view
[Tue May 31 23:21:13.983622 2022] [wsgi:error] [pid 20911] [remote 127.0.0.1:43118]     return self.dispatch(request, *args, **kwargs)
[Tue May 31 23:21:13.983625 2022] [wsgi:error] [pid 20911] [remote 127.0.0.1:43118]   File "/home/freddy/www/multitenant/venv/lib/python3.8/site-packages/rest_framework/views.py", line 509, in dispatch
[Tue May 31 23:21:13.983628 2022] [wsgi:error] [pid 20911] [remote 127.0.0.1:43118]     response = self.handle_exception(exc)
[Tue May 31 23:21:13.983630 2022] [wsgi:error] [pid 20911] [remote 127.0.0.1:43118]   File "/home/freddy/www/multitenant/venv/lib/python3.8/site-packages/rest_framework/views.py", line 469, in handle_exception
[Tue May 31 23:21:13.983632 2022] [wsgi:error] [pid 20911] [remote 127.0.0.1:43118]     self.raise_uncaught_exception(exc)
[Tue May 31 23:21:13.983634 2022] [wsgi:error] [pid 20911] [remote 127.0.0.1:43118]   File "/home/freddy/www/multitenant/venv/lib/python3.8/site-packages/rest_framework/views.py", line 480, in raise_uncaught_exception
[Tue May 31 23:21:13.983636 2022] [wsgi:error] [pid 20911] [remote 127.0.0.1:43118]     raise exc
[Tue May 31 23:21:13.983637 2022] [wsgi:error] [pid 20911] [remote 127.0.0.1:43118]   File "/home/freddy/www/multitenant/venv/lib/python3.8/site-packages/rest_framework/views.py", line 506, in dispatch
[Tue May 31 23:21:13.983639 2022] [wsgi:error] [pid 20911] [remote 127.0.0.1:43118]     response = handler(request, *args, **kwargs)
[Tue May 31 23:21:13.983641 2022] [wsgi:error] [pid 20911] [remote 127.0.0.1:43118]   File "/home/freddy/www/multitenant/demands/views.py", line 12, in get
[Tue May 31 23:21:13.983643 2022] [wsgi:error] [pid 20911] [remote 127.0.0.1:43118]     return Response(self.get_serializer_class(Demand.objects.all(), many=True).data)
[Tue May 31 23:21:13.983644 2022] [wsgi:error] [pid 20911] [remote 127.0.0.1:43118] TypeError: get_serializer_class() got an unexpected keyword argument 'many'
Exception ignored in: <function Local.__del__ at 0x7f94ef050e50>
Traceback (most recent call last):
  File "/home/freddy/www/multitenant/venv/lib/python3.8/site-packages/asgiref/local.py", line 94, in __del__
NameError: name 'TypeError' is not defined
Exception ignored in: <function Local.__del__ at 0x7f94ef050e50>
Traceback (most recent call last):
  File "/home/freddy/www/multitenant/venv/lib/python3.8/site-packages/asgiref/local.py", line 94, in __del__
NameError: name 'TypeError' is not defined
[Tue May 31 23:21:42.916016 2022] [wsgi:error] [pid 21169] [remote 127.0.0.1:43122] Internal Server Error: /demands/
[Tue May 31 23:21:42.916050 2022] [wsgi:error] [pid 21169] [remote 127.0.0.1:43122] Traceback (most recent call last):
[Tue May 31 23:21:42.916053 2022] [wsgi:error] [pid 21169] [remote 127.0.0.1:43122]   File "/home/freddy/www/multitenant/venv/lib/python3.8/site-packages/django/core/handlers/exception.py", line 55, in inner
[Tue May 31 23:21:42.916055 2022] [wsgi:error] [pid 21169] [remote 127.0.0.1:43122]     response = get_response(request)
[Tue May 31 23:21:42.916057 2022] [wsgi:error] [pid 21169] [remote 127.0.0.1:43122]   File "/home/freddy/www/multitenant/venv/lib/python3.8/site-packages/django/core/handlers/base.py", line 220, in _get_response
[Tue May 31 23:21:42.916059 2022] [wsgi:error] [pid 21169] [remote 127.0.0.1:43122]     response = response.render()
[Tue May 31 23:21:42.916061 2022] [wsgi:error] [pid 21169] [remote 127.0.0.1:43122]   File "/home/freddy/www/multitenant/venv/lib/python3.8/site-packages/django/template/response.py", line 114, in render
[Tue May 31 23:21:42.916064 2022] [wsgi:error] [pid 21169] [remote 127.0.0.1:43122]     self.content = self.rendered_content
[Tue May 31 23:21:42.916066 2022] [wsgi:error] [pid 21169] [remote 127.0.0.1:43122]   File "/home/freddy/www/multitenant/venv/lib/python3.8/site-packages/rest_framework/response.py", line 70, in rendered_content
[Tue May 31 23:21:42.916068 2022] [wsgi:error] [pid 21169] [remote 127.0.0.1:43122]     ret = renderer.render(self.data, accepted_media_type, context)
[Tue May 31 23:21:42.916071 2022] [wsgi:error] [pid 21169] [remote 127.0.0.1:43122]   File "/home/freddy/www/multitenant/venv/lib/python3.8/site-packages/rest_framework/renderers.py", line 724, in render
[Tue May 31 23:21:42.916073 2022] [wsgi:error] [pid 21169] [remote 127.0.0.1:43122]     context = self.get_context(data, accepted_media_type, renderer_context)
[Tue May 31 23:21:42.916075 2022] [wsgi:error] [pid 21169] [remote 127.0.0.1:43122]   File "/home/freddy/www/multitenant/venv/lib/python3.8/site-packages/rest_framework/renderers.py", line 702, in get_context
[Tue May 31 23:21:42.916077 2022] [wsgi:error] [pid 21169] [remote 127.0.0.1:43122]     'filter_form': self.get_filter_form(data, view, request),
[Tue May 31 23:21:42.916079 2022] [wsgi:error] [pid 21169] [remote 127.0.0.1:43122]   File "/home/freddy/www/multitenant/venv/lib/python3.8/site-packages/rest_framework/renderers.py", line 630, in get_filter_form
[Tue May 31 23:21:42.916082 2022] [wsgi:error] [pid 21169] [remote 127.0.0.1:43122]     queryset = view.get_queryset()
[Tue May 31 23:21:42.916084 2022] [wsgi:error] [pid 21169] [remote 127.0.0.1:43122]   File "/home/freddy/www/multitenant/venv/lib/python3.8/site-packages/rest_framework/generics.py", line 63, in get_queryset
[Tue May 31 23:21:42.916086 2022] [wsgi:error] [pid 21169] [remote 127.0.0.1:43122]     assert self.queryset is not None, (
[Tue May 31 23:21:42.916088 2022] [wsgi:error] [pid 21169] [remote 127.0.0.1:43122] AssertionError: 'ListCreateDemand' should either include a `queryset` attribute, or override the `get_queryset()` method.
Exception ignored in: <function Local.__del__ at 0x7f9efb0eee50>
Traceback (most recent call last):
  File "/home/freddy/www/multitenant/venv/lib/python3.8/site-packages/asgiref/local.py", line 94, in __del__
NameError: name 'TypeError' is not defined
Exception ignored in: <function Local.__del__ at 0x7f9efb0eee50>
Traceback (most recent call last):
  File "/home/freddy/www/multitenant/venv/lib/python3.8/site-packages/asgiref/local.py", line 94, in __del__
NameError: name 'TypeError' is not defined
[Tue May 31 23:22:22.470298 2022] [wsgi:error] [pid 21477] [remote 127.0.0.1:43124] Internal Server Error: /demands/
[Tue May 31 23:22:22.470337 2022] [wsgi:error] [pid 21477] [remote 127.0.0.1:43124] Traceback (most recent call last):
[Tue May 31 23:22:22.470348 2022] [wsgi:error] [pid 21477] [remote 127.0.0.1:43124]   File "/home/freddy/www/multitenant/venv/lib/python3.8/site-packages/django/core/handlers/exception.py", line 55, in inner
[Tue May 31 23:22:22.470350 2022] [wsgi:error] [pid 21477] [remote 127.0.0.1:43124]     response = get_response(request)
[Tue May 31 23:22:22.470351 2022] [wsgi:error] [pid 21477] [remote 127.0.0.1:43124]   File "/home/freddy/www/multitenant/venv/lib/python3.8/site-packages/django/core/handlers/base.py", line 197, in _get_response
[Tue May 31 23:22:22.470353 2022] [wsgi:error] [pid 21477] [remote 127.0.0.1:43124]     response = wrapped_callback(request, *callback_args, **callback_kwargs)
[Tue May 31 23:22:22.470355 2022] [wsgi:error] [pid 21477] [remote 127.0.0.1:43124]   File "/home/freddy/www/multitenant/venv/lib/python3.8/site-packages/django/views/decorators/csrf.py", line 54, in wrapped_view
[Tue May 31 23:22:22.470356 2022] [wsgi:error] [pid 21477] [remote 127.0.0.1:43124]     return view_func(*args, **kwargs)
[Tue May 31 23:22:22.470358 2022] [wsgi:error] [pid 21477] [remote 127.0.0.1:43124]   File "/home/freddy/www/multitenant/venv/lib/python3.8/site-packages/django/views/generic/base.py", line 84, in view
[Tue May 31 23:22:22.470360 2022] [wsgi:error] [pid 21477] [remote 127.0.0.1:43124]     return self.dispatch(request, *args, **kwargs)
[Tue May 31 23:22:22.470361 2022] [wsgi:error] [pid 21477] [remote 127.0.0.1:43124]   File "/home/freddy/www/multitenant/venv/lib/python3.8/site-packages/rest_framework/views.py", line 509, in dispatch
[Tue May 31 23:22:22.470363 2022] [wsgi:error] [pid 21477] [remote 127.0.0.1:43124]     response = self.handle_exception(exc)
[Tue May 31 23:22:22.470365 2022] [wsgi:error] [pid 21477] [remote 127.0.0.1:43124]   File "/home/freddy/www/multitenant/venv/lib/python3.8/site-packages/rest_framework/views.py", line 469, in handle_exception
[Tue May 31 23:22:22.470366 2022] [wsgi:error] [pid 21477] [remote 127.0.0.1:43124]     self.raise_uncaught_exception(exc)
[Tue May 31 23:22:22.470368 2022] [wsgi:error] [pid 21477] [remote 127.0.0.1:43124]   File "/home/freddy/www/multitenant/venv/lib/python3.8/site-packages/rest_framework/views.py", line 480, in raise_uncaught_exception
[Tue May 31 23:22:22.470370 2022] [wsgi:error] [pid 21477] [remote 127.0.0.1:43124]     raise exc
[Tue May 31 23:22:22.470371 2022] [wsgi:error] [pid 21477] [remote 127.0.0.1:43124]   File "/home/freddy/www/multitenant/venv/lib/python3.8/site-packages/rest_framework/views.py", line 506, in dispatch
[Tue May 31 23:22:22.470373 2022] [wsgi:error] [pid 21477] [remote 127.0.0.1:43124]     response = handler(request, *args, **kwargs)
[Tue May 31 23:22:22.470381 2022] [wsgi:error] [pid 21477] [remote 127.0.0.1:43124]   File "/home/freddy/www/multitenant/demands/views.py", line 14, in get
[Tue May 31 23:22:22.470382 2022] [wsgi:error] [pid 21477] [remote 127.0.0.1:43124]     return Response(DemandSerializer(queryset, many=True).data)
[Tue May 31 23:22:22.470384 2022] [wsgi:error] [pid 21477] [remote 127.0.0.1:43124] NameError: name 'queryset' is not defined
Exception ignored in: <function Local.__del__ at 0x7f66815f0e50>
Traceback (most recent call last):
  File "/home/freddy/www/multitenant/venv/lib/python3.8/site-packages/asgiref/local.py", line 94, in __del__
NameError: name 'TypeError' is not defined
Exception ignored in: <function Local.__del__ at 0x7f66815f0e50>
Traceback (most recent call last):
  File "/home/freddy/www/multitenant/venv/lib/python3.8/site-packages/asgiref/local.py", line 94, in __del__
NameError: name 'TypeError' is not defined
[Tue May 31 23:22:36.697668 2022] [wsgi:error] [pid 21712] [remote 127.0.0.1:43128] Internal Server Error: /demands/
[Tue May 31 23:22:36.697721 2022] [wsgi:error] [pid 21712] [remote 127.0.0.1:43128] Traceback (most recent call last):
[Tue May 31 23:22:36.697724 2022] [wsgi:error] [pid 21712] [remote 127.0.0.1:43128]   File "/home/freddy/www/multitenant/venv/lib/python3.8/site-packages/django/core/handlers/exception.py", line 55, in inner
[Tue May 31 23:22:36.697726 2022] [wsgi:error] [pid 21712] [remote 127.0.0.1:43128]     response = get_response(request)
[Tue May 31 23:22:36.697737 2022] [wsgi:error] [pid 21712] [remote 127.0.0.1:43128]   File "/home/freddy/www/multitenant/venv/lib/python3.8/site-packages/django/core/handlers/base.py", line 197, in _get_response
[Tue May 31 23:22:36.697739 2022] [wsgi:error] [pid 21712] [remote 127.0.0.1:43128]     response = wrapped_callback(request, *callback_args, **callback_kwargs)
[Tue May 31 23:22:36.697741 2022] [wsgi:error] [pid 21712] [remote 127.0.0.1:43128]   File "/home/freddy/www/multitenant/venv/lib/python3.8/site-packages/django/views/decorators/csrf.py", line 54, in wrapped_view
[Tue May 31 23:22:36.697742 2022] [wsgi:error] [pid 21712] [remote 127.0.0.1:43128]     return view_func(*args, **kwargs)
[Tue May 31 23:22:36.697744 2022] [wsgi:error] [pid 21712] [remote 127.0.0.1:43128]   File "/home/freddy/www/multitenant/venv/lib/python3.8/site-packages/django/views/generic/base.py", line 84, in view
[Tue May 31 23:22:36.697756 2022] [wsgi:error] [pid 21712] [remote 127.0.0.1:43128]     return self.dispatch(request, *args, **kwargs)
[Tue May 31 23:22:36.697757 2022] [wsgi:error] [pid 21712] [remote 127.0.0.1:43128]   File "/home/freddy/www/multitenant/venv/lib/python3.8/site-packages/rest_framework/views.py", line 509, in dispatch
[Tue May 31 23:22:36.697759 2022] [wsgi:error] [pid 21712] [remote 127.0.0.1:43128]     response = self.handle_exception(exc)
[Tue May 31 23:22:36.697761 2022] [wsgi:error] [pid 21712] [remote 127.0.0.1:43128]   File "/home/freddy/www/multitenant/venv/lib/python3.8/site-packages/rest_framework/views.py", line 469, in handle_exception
[Tue May 31 23:22:36.697763 2022] [wsgi:error] [pid 21712] [remote 127.0.0.1:43128]     self.raise_uncaught_exception(exc)
[Tue May 31 23:22:36.697765 2022] [wsgi:error] [pid 21712] [remote 127.0.0.1:43128]   File "/home/freddy/www/multitenant/venv/lib/python3.8/site-packages/rest_framework/views.py", line 480, in raise_uncaught_exception
[Tue May 31 23:22:36.697766 2022] [wsgi:error] [pid 21712] [remote 127.0.0.1:43128]     raise exc
[Tue May 31 23:22:36.697768 2022] [wsgi:error] [pid 21712] [remote 127.0.0.1:43128]   File "/home/freddy/www/multitenant/venv/lib/python3.8/site-packages/rest_framework/views.py", line 506, in dispatch
[Tue May 31 23:22:36.697770 2022] [wsgi:error] [pid 21712] [remote 127.0.0.1:43128]     response = handler(request, *args, **kwargs)
[Tue May 31 23:22:36.697772 2022] [wsgi:error] [pid 21712] [remote 127.0.0.1:43128]   File "/home/freddy/www/multitenant/demands/views.py", line 14, in get
[Tue May 31 23:22:36.697773 2022] [wsgi:error] [pid 21712] [remote 127.0.0.1:43128]     return Response(DemandSerializer(self.queryset, many=True).data)
[Tue May 31 23:22:36.697775 2022] [wsgi:error] [pid 21712] [remote 127.0.0.1:43128]   File "/home/freddy/www/multitenant/venv/lib/python3.8/site-packages/rest_framework/serializers.py", line 768, in data
[Tue May 31 23:22:36.697777 2022] [wsgi:error] [pid 21712] [remote 127.0.0.1:43128]     ret = super().data
[Tue May 31 23:22:36.697779 2022] [wsgi:error] [pid 21712] [remote 127.0.0.1:43128]   File "/home/freddy/www/multitenant/venv/lib/python3.8/site-packages/rest_framework/serializers.py", line 253, in data
[Tue May 31 23:22:36.697780 2022] [wsgi:error] [pid 21712] [remote 127.0.0.1:43128]     self._data = self.to_representation(self.instance)
[Tue May 31 23:22:36.697782 2022] [wsgi:error] [pid 21712] [remote 127.0.0.1:43128]   File "/home/freddy/www/multitenant/venv/lib/python3.8/site-packages/rest_framework/serializers.py", line 686, in to_representation
[Tue May 31 23:22:36.697784 2022] [wsgi:error] [pid 21712] [remote 127.0.0.1:43128]     return [
[Tue May 31 23:22:36.697786 2022] [wsgi:error] [pid 21712] [remote 127.0.0.1:43128]   File "/home/freddy/www/multitenant/venv/lib/python3.8/site-packages/django/db/models/query.py", line 320, in __iter__
[Tue May 31 23:22:36.697787 2022] [wsgi:error] [pid 21712] [remote 127.0.0.1:43128]     self._fetch_all()
[Tue May 31 23:22:36.697789 2022] [wsgi:error] [pid 21712] [remote 127.0.0.1:43128]   File "/home/freddy/www/multitenant/venv/lib/python3.8/site-packages/rest_framework/views.py", line 131, in force_evaluation
[Tue May 31 23:22:36.697793 2022] [wsgi:error] [pid 21712] [remote 127.0.0.1:43128]     raise RuntimeError(
[Tue May 31 23:22:36.697795 2022] [wsgi:error] [pid 21712] [remote 127.0.0.1:43128] RuntimeError: Do not evaluate the `.queryset` attribute directly, as the result will be cached and reused between requests. Use `.all()` or call `.get_queryset()` instead.
Exception ignored in: <function Local.__del__ at 0x7f96ad0efe50>
Traceback (most recent call last):
  File "/home/freddy/www/multitenant/venv/lib/python3.8/site-packages/asgiref/local.py", line 94, in __del__
NameError: name 'TypeError' is not defined
Exception ignored in: <function Local.__del__ at 0x7f96ad0efe50>
Traceback (most recent call last):
  File "/home/freddy/www/multitenant/venv/lib/python3.8/site-packages/asgiref/local.py", line 94, in __del__
NameError: name 'TypeError' is not defined
[Tue May 31 23:23:12.335494 2022] [wsgi:error] [pid 21957] [remote 127.0.0.1:43144] Invalid HTTP_HOST header: 'toni.multi.mydev'. You may need to add 'toni.multi.mydev' to ALLOWED_HOSTS.
[Tue May 31 23:23:12.352174 2022] [wsgi:error] [pid 21957] [remote 127.0.0.1:43144] Bad Request: /demands/
Exception ignored in: <function Local.__del__ at 0x7f6b5d34be50>
Traceback (most recent call last):
  File "/home/freddy/www/multitenant/venv/lib/python3.8/site-packages/asgiref/local.py", line 94, in __del__
NameError: name 'TypeError' is not defined
Exception ignored in: <function Local.__del__ at 0x7f6b5d34be50>
Traceback (most recent call last):
  File "/home/freddy/www/multitenant/venv/lib/python3.8/site-packages/asgiref/local.py", line 94, in __del__
NameError: name 'TypeError' is not defined
Exception ignored in: <function Local.__del__ at 0x7f358ad1be50>
Traceback (most recent call last):
  File "/home/freddy/www/multitenant/venv/lib/python3.8/site-packages/asgiref/local.py", line 94, in __del__
NameError: name 'TypeError' is not defined
[Tue May 31 23:25:25.832303 2022] [wsgi:error] [pid 22849] [remote 127.0.0.1:43164] Not Found: /
Exception ignored in: <function Local.__del__ at 0x7f5847ab8e50>
Traceback (most recent call last):
  File "/home/freddy/www/multitenant/venv/lib/python3.8/site-packages/asgiref/local.py", line 94, in __del__
NameError: name 'TypeError' is not defined
[Tue May 31 23:27:37.245010 2022] [wsgi:error] [pid 23470] [remote 127.0.0.1:43170] Internal Server Error: /demands/
[Tue May 31 23:27:37.245050 2022] [wsgi:error] [pid 23470] [remote 127.0.0.1:43170] Traceback (most recent call last):
[Tue May 31 23:27:37.245054 2022] [wsgi:error] [pid 23470] [remote 127.0.0.1:43170]   File "/home/freddy/www/multitenant/venv/lib/python3.8/site-packages/django/core/handlers/exception.py", line 55, in inner
[Tue May 31 23:27:37.245057 2022] [wsgi:error] [pid 23470] [remote 127.0.0.1:43170]     response = get_response(request)
[Tue May 31 23:27:37.245059 2022] [wsgi:error] [pid 23470] [remote 127.0.0.1:43170]   File "/home/freddy/www/multitenant/venv/lib/python3.8/site-packages/django/core/handlers/base.py", line 197, in _get_response
[Tue May 31 23:27:37.245062 2022] [wsgi:error] [pid 23470] [remote 127.0.0.1:43170]     response = wrapped_callback(request, *callback_args, **callback_kwargs)
[Tue May 31 23:27:37.245064 2022] [wsgi:error] [pid 23470] [remote 127.0.0.1:43170]   File "/home/freddy/www/multitenant/venv/lib/python3.8/site-packages/django/views/decorators/csrf.py", line 54, in wrapped_view
[Tue May 31 23:27:37.245066 2022] [wsgi:error] [pid 23470] [remote 127.0.0.1:43170]     return view_func(*args, **kwargs)
[Tue May 31 23:27:37.245069 2022] [wsgi:error] [pid 23470] [remote 127.0.0.1:43170]   File "/home/freddy/www/multitenant/venv/lib/python3.8/site-packages/django/views/generic/base.py", line 84, in view
[Tue May 31 23:27:37.245072 2022] [wsgi:error] [pid 23470] [remote 127.0.0.1:43170]     return self.dispatch(request, *args, **kwargs)
[Tue May 31 23:27:37.245074 2022] [wsgi:error] [pid 23470] [remote 127.0.0.1:43170]   File "/home/freddy/www/multitenant/venv/lib/python3.8/site-packages/rest_framework/views.py", line 509, in dispatch
[Tue May 31 23:27:37.245085 2022] [wsgi:error] [pid 23470] [remote 127.0.0.1:43170]     response = self.handle_exception(exc)
[Tue May 31 23:27:37.245087 2022] [wsgi:error] [pid 23470] [remote 127.0.0.1:43170]   File "/home/freddy/www/multitenant/venv/lib/python3.8/site-packages/rest_framework/views.py", line 469, in handle_exception
[Tue May 31 23:27:37.245090 2022] [wsgi:error] [pid 23470] [remote 127.0.0.1:43170]     self.raise_uncaught_exception(exc)
[Tue May 31 23:27:37.245092 2022] [wsgi:error] [pid 23470] [remote 127.0.0.1:43170]   File "/home/freddy/www/multitenant/venv/lib/python3.8/site-packages/rest_framework/views.py", line 480, in raise_uncaught_exception
[Tue May 31 23:27:37.245095 2022] [wsgi:error] [pid 23470] [remote 127.0.0.1:43170]     raise exc
[Tue May 31 23:27:37.245097 2022] [wsgi:error] [pid 23470] [remote 127.0.0.1:43170]   File "/home/freddy/www/multitenant/venv/lib/python3.8/site-packages/rest_framework/views.py", line 506, in dispatch
[Tue May 31 23:27:37.245100 2022] [wsgi:error] [pid 23470] [remote 127.0.0.1:43170]     response = handler(request, *args, **kwargs)
[Tue May 31 23:27:37.245102 2022] [wsgi:error] [pid 23470] [remote 127.0.0.1:43170]   File "/home/freddy/www/multitenant/demands/views.py", line 14, in get
[Tue May 31 23:27:37.245105 2022] [wsgi:error] [pid 23470] [remote 127.0.0.1:43170]     return Response(self.get_serializer(self.queryset, many=True).data)
[Tue May 31 23:27:37.245107 2022] [wsgi:error] [pid 23470] [remote 127.0.0.1:43170]   File "/home/freddy/www/multitenant/venv/lib/python3.8/site-packages/rest_framework/serializers.py", line 768, in data
[Tue May 31 23:27:37.245110 2022] [wsgi:error] [pid 23470] [remote 127.0.0.1:43170]     ret = super().data
[Tue May 31 23:27:37.245113 2022] [wsgi:error] [pid 23470] [remote 127.0.0.1:43170]   File "/home/freddy/www/multitenant/venv/lib/python3.8/site-packages/rest_framework/serializers.py", line 253, in data
[Tue May 31 23:27:37.245115 2022] [wsgi:error] [pid 23470] [remote 127.0.0.1:43170]     self._data = self.to_representation(self.instance)
[Tue May 31 23:27:37.245117 2022] [wsgi:error] [pid 23470] [remote 127.0.0.1:43170]   File "/home/freddy/www/multitenant/venv/lib/python3.8/site-packages/rest_framework/serializers.py", line 686, in to_representation
[Tue May 31 23:27:37.245119 2022] [wsgi:error] [pid 23470] [remote 127.0.0.1:43170]     return [
[Tue May 31 23:27:37.245121 2022] [wsgi:error] [pid 23470] [remote 127.0.0.1:43170]   File "/home/freddy/www/multitenant/venv/lib/python3.8/site-packages/django/db/models/query.py", line 320, in __iter__
[Tue May 31 23:27:37.245123 2022] [wsgi:error] [pid 23470] [remote 127.0.0.1:43170]     self._fetch_all()
[Tue May 31 23:27:37.245124 2022] [wsgi:error] [pid 23470] [remote 127.0.0.1:43170]   File "/home/freddy/www/multitenant/venv/lib/python3.8/site-packages/rest_framework/views.py", line 131, in force_evaluation
[Tue May 31 23:27:37.245126 2022] [wsgi:error] [pid 23470] [remote 127.0.0.1:43170]     raise RuntimeError(
[Tue May 31 23:27:37.245128 2022] [wsgi:error] [pid 23470] [remote 127.0.0.1:43170] RuntimeError: Do not evaluate the `.queryset` attribute directly, as the result will be cached and reused between requests. Use `.all()` or call `.get_queryset()` instead.
Exception ignored in: <function Local.__del__ at 0x7f3d4ca88e50>
Traceback (most recent call last):
  File "/home/freddy/www/multitenant/venv/lib/python3.8/site-packages/asgiref/local.py", line 94, in __del__
NameError: name 'TypeError' is not defined
Exception ignored in: <function Local.__del__ at 0x7f3d4ca88e50>
Traceback (most recent call last):
  File "/home/freddy/www/multitenant/venv/lib/python3.8/site-packages/asgiref/local.py", line 94, in __del__
NameError: name 'TypeError' is not defined
Exception ignored in: <function Local.__del__ at 0x7f1c60f64e50>
Traceback (most recent call last):
  File "/home/freddy/www/multitenant/venv/lib/python3.8/site-packages/asgiref/local.py", line 94, in __del__
NameError: name 'TypeError' is not defined
[Wed Jun 01 07:49:27.609677 2022] [wsgi:error] [pid 1093] [remote 127.0.0.1:48918] Internal Server Error: /favicon.ico
[Wed Jun 01 07:49:27.610026 2022] [wsgi:error] [pid 1093] [remote 127.0.0.1:48918] Traceback (most recent call last):
[Wed Jun 01 07:49:27.610028 2022] [wsgi:error] [pid 1093] [remote 127.0.0.1:48918]   File "/home/freddy/www/multitenant/venv/lib/python3.8/site-packages/django/db/backends/base/base.py", line 244, in ensure_connection
[Wed Jun 01 07:49:27.610030 2022] [wsgi:error] [pid 1093] [remote 127.0.0.1:48918]     self.connect()
[Wed Jun 01 07:49:27.610031 2022] [wsgi:error] [pid 1093] [remote 127.0.0.1:48918]   File "/home/freddy/www/multitenant/venv/lib/python3.8/site-packages/django/utils/asyncio.py", line 26, in inner
[Wed Jun 01 07:49:27.610033 2022] [wsgi:error] [pid 1093] [remote 127.0.0.1:48918]     return func(*args, **kwargs)
[Wed Jun 01 07:49:27.610034 2022] [wsgi:error] [pid 1093] [remote 127.0.0.1:48918]   File "/home/freddy/www/multitenant/venv/lib/python3.8/site-packages/django/db/backends/base/base.py", line 225, in connect
[Wed Jun 01 07:49:27.610036 2022] [wsgi:error] [pid 1093] [remote 127.0.0.1:48918]     self.connection = self.get_new_connection(conn_params)
[Wed Jun 01 07:49:27.610037 2022] [wsgi:error] [pid 1093] [remote 127.0.0.1:48918]   File "/home/freddy/www/multitenant/venv/lib/python3.8/site-packages/django/utils/asyncio.py", line 26, in inner
[Wed Jun 01 07:49:27.610038 2022] [wsgi:error] [pid 1093] [remote 127.0.0.1:48918]     return func(*args, **kwargs)
[Wed Jun 01 07:49:27.610040 2022] [wsgi:error] [pid 1093] [remote 127.0.0.1:48918]   File "/home/freddy/www/multitenant/venv/lib/python3.8/site-packages/django/db/backends/postgresql/base.py", line 203, in get_new_connection
[Wed Jun 01 07:49:27.610041 2022] [wsgi:error] [pid 1093] [remote 127.0.0.1:48918]     connection = Database.connect(**conn_params)
[Wed Jun 01 07:49:27.610042 2022] [wsgi:error] [pid 1093] [remote 127.0.0.1:48918]   File "/home/freddy/www/multitenant/venv/lib/python3.8/site-packages/psycopg2/__init__.py", line 122, in connect
[Wed Jun 01 07:49:27.610044 2022] [wsgi:error] [pid 1093] [remote 127.0.0.1:48918]     conn = _connect(dsn, connection_factory=connection_factory, **kwasync)
[Wed Jun 01 07:49:27.610045 2022] [wsgi:error] [pid 1093] [remote 127.0.0.1:48918] psycopg2.OperationalError: connection to server at "127.0.0.1", port 5432 failed: Connection refused
[Wed Jun 01 07:49:27.610047 2022] [wsgi:error] [pid 1093] [remote 127.0.0.1:48918] \tIs the server running on that host and accepting TCP/IP connections?
[Wed Jun 01 07:49:27.610048 2022] [wsgi:error] [pid 1093] [remote 127.0.0.1:48918] 
[Wed Jun 01 07:49:27.610049 2022] [wsgi:error] [pid 1093] [remote 127.0.0.1:48918] 
[Wed Jun 01 07:49:27.610050 2022] [wsgi:error] [pid 1093] [remote 127.0.0.1:48918] The above exception was the direct cause of the following exception:
[Wed Jun 01 07:49:27.610052 2022] [wsgi:error] [pid 1093] [remote 127.0.0.1:48918] 
[Wed Jun 01 07:49:27.610053 2022] [wsgi:error] [pid 1093] [remote 127.0.0.1:48918] Traceback (most recent call last):
[Wed Jun 01 07:49:27.610054 2022] [wsgi:error] [pid 1093] [remote 127.0.0.1:48918]   File "/home/freddy/www/multitenant/venv/lib/python3.8/site-packages/django/core/handlers/exception.py", line 55, in inner
[Wed Jun 01 07:49:27.610056 2022] [wsgi:error] [pid 1093] [remote 127.0.0.1:48918]     response = get_response(request)
[Wed Jun 01 07:49:27.610057 2022] [wsgi:error] [pid 1093] [remote 127.0.0.1:48918]   File "/home/freddy/www/multitenant/venv/lib/python3.8/site-packages/django/utils/deprecation.py", line 133, in __call__
[Wed Jun 01 07:49:27.610058 2022] [wsgi:error] [pid 1093] [remote 127.0.0.1:48918]     response = self.process_request(request)
[Wed Jun 01 07:49:27.610060 2022] [wsgi:error] [pid 1093] [remote 127.0.0.1:48918]   File "/home/freddy/www/multitenant/venv/lib/python3.8/site-packages/django_tenants/middleware/main.py", line 39, in process_request
[Wed Jun 01 07:49:27.610061 2022] [wsgi:error] [pid 1093] [remote 127.0.0.1:48918]     tenant = self.get_tenant(domain_model, hostname)
[Wed Jun 01 07:49:27.610066 2022] [wsgi:error] [pid 1093] [remote 127.0.0.1:48918]   File "/home/freddy/www/multitenant/venv/lib/python3.8/site-packages/django_tenants/middleware/main.py", line 27, in get_tenant
[Wed Jun 01 07:49:27.610067 2022] [wsgi:error] [pid 1093] [remote 127.0.0.1:48918]     domain = domain_model.objects.select_related('tenant').get(domain=hostname)
[Wed Jun 01 07:49:27.610068 2022] [wsgi:error] [pid 1093] [remote 127.0.0.1:48918]   File "/home/freddy/www/multitenant/venv/lib/python3.8/site-packages/django/db/models/query.py", line 492, in get
[Wed Jun 01 07:49:27.610070 2022] [wsgi:error] [pid 1093] [remote 127.0.0.1:48918]     num = len(clone)
[Wed Jun 01 07:49:27.610071 2022] [wsgi:error] [pid 1093] [remote 127.0.0.1:48918]   File "/home/freddy/www/multitenant/venv/lib/python3.8/site-packages/django/db/models/query.py", line 302, in __len__
[Wed Jun 01 07:49:27.610072 2022] [wsgi:error] [pid 1093] [remote 127.0.0.1:48918]     self._fetch_all()
[Wed Jun 01 07:49:27.610074 2022] [wsgi:error] [pid 1093] [remote 127.0.0.1:48918]   File "/home/freddy/www/multitenant/venv/lib/python3.8/site-packages/django/db/models/query.py", line 1507, in _fetch_all
[Wed Jun 01 07:49:27.610075 2022] [wsgi:error] [pid 1093] [remote 127.0.0.1:48918]     self._result_cache = list(self._iterable_class(self))
[Wed Jun 01 07:49:27.610076 2022] [wsgi:error] [pid 1093] [remote 127.0.0.1:48918]   File "/home/freddy/www/multitenant/venv/lib/python3.8/site-packages/django/db/models/query.py", line 57, in __iter__
[Wed Jun 01 07:49:27.610077 2022] [wsgi:error] [pid 1093] [remote 127.0.0.1:48918]     results = compiler.execute_sql(
[Wed Jun 01 07:49:27.610079 2022] [wsgi:error] [pid 1093] [remote 127.0.0.1:48918]   File "/home/freddy/www/multitenant/venv/lib/python3.8/site-packages/django/db/models/sql/compiler.py", line 1359, in execute_sql
[Wed Jun 01 07:49:27.610080 2022] [wsgi:error] [pid 1093] [remote 127.0.0.1:48918]     cursor = self.connection.cursor()
[Wed Jun 01 07:49:27.610081 2022] [wsgi:error] [pid 1093] [remote 127.0.0.1:48918]   File "/home/freddy/www/multitenant/venv/lib/python3.8/site-packages/django/utils/asyncio.py", line 26, in inner
[Wed Jun 01 07:49:27.610083 2022] [wsgi:error] [pid 1093] [remote 127.0.0.1:48918]     return func(*args, **kwargs)
[Wed Jun 01 07:49:27.610084 2022] [wsgi:error] [pid 1093] [remote 127.0.0.1:48918]   File "/home/freddy/www/multitenant/venv/lib/python3.8/site-packages/django/db/backends/base/base.py", line 284, in cursor
[Wed Jun 01 07:49:27.610085 2022] [wsgi:error] [pid 1093] [remote 127.0.0.1:48918]     return self._cursor()
[Wed Jun 01 07:49:27.610087 2022] [wsgi:error] [pid 1093] [remote 127.0.0.1:48918]   File "/home/freddy/www/multitenant/venv/lib/python3.8/site-packages/django_tenants/postgresql_backend/base.py", line 122, in _cursor
[Wed Jun 01 07:49:27.610088 2022] [wsgi:error] [pid 1093] [remote 127.0.0.1:48918]     cursor = super()._cursor()
[Wed Jun 01 07:49:27.610089 2022] [wsgi:error] [pid 1093] [remote 127.0.0.1:48918]   File "/home/freddy/www/multitenant/venv/lib/python3.8/site-packages/django/db/backends/base/base.py", line 260, in _cursor
[Wed Jun 01 07:49:27.610090 2022] [wsgi:error] [pid 1093] [remote 127.0.0.1:48918]     self.ensure_connection()
[Wed Jun 01 07:49:27.610092 2022] [wsgi:error] [pid 1093] [remote 127.0.0.1:48918]   File "/home/freddy/www/multitenant/venv/lib/python3.8/site-packages/django/utils/asyncio.py", line 26, in inner
[Wed Jun 01 07:49:27.610093 2022] [wsgi:error] [pid 1093] [remote 127.0.0.1:48918]     return func(*args, **kwargs)
[Wed Jun 01 07:49:27.610094 2022] [wsgi:error] [pid 1093] [remote 127.0.0.1:48918]   File "/home/freddy/www/multitenant/venv/lib/python3.8/site-packages/django/db/backends/base/base.py", line 244, in ensure_connection
[Wed Jun 01 07:49:27.610096 2022] [wsgi:error] [pid 1093] [remote 127.0.0.1:48918]     self.connect()
[Wed Jun 01 07:49:27.610097 2022] [wsgi:error] [pid 1093] [remote 127.0.0.1:48918]   File "/home/freddy/www/multitenant/venv/lib/python3.8/site-packages/django/db/utils.py", line 91, in __exit__
[Wed Jun 01 07:49:27.610100 2022] [wsgi:error] [pid 1093] [remote 127.0.0.1:48918]     raise dj_exc_value.with_traceback(traceback) from exc_value
[Wed Jun 01 07:49:27.610101 2022] [wsgi:error] [pid 1093] [remote 127.0.0.1:48918]   File "/home/freddy/www/multitenant/venv/lib/python3.8/site-packages/django/db/backends/base/base.py", line 244, in ensure_connection
[Wed Jun 01 07:49:27.610102 2022] [wsgi:error] [pid 1093] [remote 127.0.0.1:48918]     self.connect()
[Wed Jun 01 07:49:27.610104 2022] [wsgi:error] [pid 1093] [remote 127.0.0.1:48918]   File "/home/freddy/www/multitenant/venv/lib/python3.8/site-packages/django/utils/asyncio.py", line 26, in inner
[Wed Jun 01 07:49:27.610105 2022] [wsgi:error] [pid 1093] [remote 127.0.0.1:48918]     return func(*args, **kwargs)
[Wed Jun 01 07:49:27.610106 2022] [wsgi:error] [pid 1093] [remote 127.0.0.1:48918]   File "/home/freddy/www/multitenant/venv/lib/python3.8/site-packages/django/db/backends/base/base.py", line 225, in connect
[Wed Jun 01 07:49:27.610107 2022] [wsgi:error] [pid 1093] [remote 127.0.0.1:48918]     self.connection = self.get_new_connection(conn_params)
[Wed Jun 01 07:49:27.610109 2022] [wsgi:error] [pid 1093] [remote 127.0.0.1:48918]   File "/home/freddy/www/multitenant/venv/lib/python3.8/site-packages/django/utils/asyncio.py", line 26, in inner
[Wed Jun 01 07:49:27.610110 2022] [wsgi:error] [pid 1093] [remote 127.0.0.1:48918]     return func(*args, **kwargs)
[Wed Jun 01 07:49:27.610111 2022] [wsgi:error] [pid 1093] [remote 127.0.0.1:48918]   File "/home/freddy/www/multitenant/venv/lib/python3.8/site-packages/django/db/backends/postgresql/base.py", line 203, in get_new_connection
[Wed Jun 01 07:49:27.610113 2022] [wsgi:error] [pid 1093] [remote 127.0.0.1:48918]     connection = Database.connect(**conn_params)
[Wed Jun 01 07:49:27.610114 2022] [wsgi:error] [pid 1093] [remote 127.0.0.1:48918]   File "/home/freddy/www/multitenant/venv/lib/python3.8/site-packages/psycopg2/__init__.py", line 122, in connect
[Wed Jun 01 07:49:27.610115 2022] [wsgi:error] [pid 1093] [remote 127.0.0.1:48918]     conn = _connect(dsn, connection_factory=connection_factory, **kwasync)
[Wed Jun 01 07:49:27.610116 2022] [wsgi:error] [pid 1093] [remote 127.0.0.1:48918] django.db.utils.OperationalError: connection to server at "127.0.0.1", port 5432 failed: Connection refused
[Wed Jun 01 07:49:27.610118 2022] [wsgi:error] [pid 1093] [remote 127.0.0.1:48918] \tIs the server running on that host and accepting TCP/IP connections?
[Wed Jun 01 07:49:27.610119 2022] [wsgi:error] [pid 1093] [remote 127.0.0.1:48918] 
[Wed Jun 01 08:30:55.805336 2022] [wsgi:error] [pid 1093] [remote 127.0.0.1:48922] Not Found: /favicon.ico
